Workbook

Sheet Management Discussion
A1: HARROW RIDGE ENVIRONMENTAL SERVICES
A2: Management Discussion: Fiscal Year Ended September 30, 2026
A3: Synthetic test data. Fictional company; not based on any real business.
A5: Results
A6: Fiscal 2026 revenue was $46.6 million and EBITDA was $9.7 million. Adjusted EBITDA, which normalizes recycling commodity prices and excludes temporary South fleet transition costs, was $11.5 million. Price increases implemented in January were realized broadly across our territories, and cost inflation was largely offset by pricing.
A8: Cash generation
A9: The business continues to convert earnings to cash efficiently. Free cash flow was $6.7 million, a 69% conversion rate, and capital spending has normalized following the fleet investments of prior years.
A11: Fleet
A12: Our fleet of 152 trucks in service is in good condition. South has experienced higher-than-normal maintenance activity, which we are addressing with temporary rental units; we expect South to return to normal operations in the first half of fiscal 2027.
A14: Territories
A15: North delivered an excellent year, with route density gains from the new routing software and $1.2 million of annualized new contract wins. East margins were affected in the fourth quarter by a disposal rate change at a third-party landfill, which we expect to recover through pricing. South continues to improve.
A17: Customers
... A23: Chief Executive Officer and Chief Financial Officer

Sheet P&L Summary
A1: HARROW RIDGE ENVIRONMENTAL SERVICES
A2: Income Statement Summary, Fiscal Year Ended September 30, 2026
A3: $ in thousands
A4: Accrual basis, US GAAP, unaudited management accounts. Finance leases recognized under ASC 842. Synthetic test data. Fictional company; not based on any real business.
B6: Q1 FY26 (Oct-Dec) | C6: Q2 FY26 (Jan-Mar) | D6: Q3 FY26 (Apr-Jun) | E6: Q4 FY26 (Jul-Sep) | F6: FY2026 Actual | G6: FY2026 Budget | H6: Variance $ | I6: Variance % | J6: FY2025 Actual
A7: Revenue
A8: Commercial Front-Load Collection | B8: =SUM('Monthly P&L'!B8:D8) -> 6355 | C8: =SUM('Monthly P&L'!E8:G8) -> 6571 | D8: =SUM('Monthly P&L'!H8:J8) -> 6908 | E8: =SUM('Monthly P&L'!K8:M8) -> 6998 | F8: =SUM(B8:E8) -> 26832 | G8: ='Monthly P&L'!N46 -> 26777 | H8: =F8-G8 -> 55 | I8: =IF(G8=0,0,H8/ABS(G8)) -> 0.0020540016 | J8: ='Monthly P&L'!N84 -> 24811
A9: Roll-Off & Industrial Collection | B9: =SUM('Monthly P&L'!B9:D9) -> 2788 | C9: =SUM('Monthly P&L'!E9:G9) -> 2673 | D9: =SUM('Monthly P&L'!H9:J9) -> 3445 | E9: =SUM('Monthly P&L'!K9:M9) -> 3465 | F9: =SUM(B9:E9) -> 12371 | G9: ='Monthly P&L'!N47 -> 12354 | H9: =F9-G9 -> 17 | I9: =IF(G9=0,0,H9/ABS(G9)) -> 0.0013760725 | J9: ='Monthly P&L'!N85 -> 11442
A10: Fuel Surcharge & Environmental Fees | B10: =SUM('Monthly P&L'!B10:D10) -> 774 | C10: =SUM('Monthly P&L'!E10:G10) -> 828 | D10: =SUM('Monthly P&L'!H10:J10) -> 884 | E10: =SUM('Monthly P&L'!K10:M10) -> 918 | F10: =SUM(B10:E10) -> 3404 | G10: ='Monthly P&L'!N48 -> 3327 | H10: =F10-G10 -> 77 | I10: =IF(G10=0,0,H10/ABS(G10)) -> 0.023143974 | J10: ='Monthly P&L'!N86 -> 3082
A11: Recycling Commodity Sales | B11: =SUM('Monthly P&L'!B11:D11) -> 823 | C11: =SUM('Monthly P&L'!E11:G11) -> 708 | D11: =SUM('Monthly P&L'!H11:J11) -> 605 | E11: =SUM('Monthly P&L'!K11:M11) -> 527 | F11: =SUM(B11:E11) -> 2663 | G11: ='Monthly P&L'!N49 -> 3168 | H11: =F11-G11 -> -505 | I11: =IF(G11=0,0,H11/ABS(G11)) -> -0.15940657 | J11: ='Monthly P&L'!N87 -> 3720
A12: Processing & Other Revenue | B12: =SUM('Monthly P&L'!B12:D12) -> 345 | C12: =SUM('Monthly P&L'!E12:G12) -> 345 | D12: =SUM('Monthly P&L'!H12:J12) -> 345 | E12: =SUM('Monthly P&L'!K12:M12) -> 345 | F12: =SUM(B12:E12) -> 1380 | G12: ='Monthly P&L'!N50 -> 1380 | H12: =F12-G12 -> 0 | I12: =IF(G12=0,0,H12/ABS(G12)) -> 0 | J12: ='Monthly P&L'!N88 -> 1380
A13: Total Revenue | B13: =SUM('Monthly P&L'!B13:D13) -> 11085 | C13: =SUM('Monthly P&L'!E13:G13) -> 11125 | D13: =SUM('Monthly P&L'!H13:J13) -> 12187 | E13: =SUM('Monthly P&L'!K13:M13) -> 12253 | F13: =SUM(B13:E13) -> 46650 | G13: ='Monthly P&L'!N51 -> 47006 | H13: =F13-G13 -> -356 | I13: =IF(G13=0,0,H13/ABS(G13)) -> -0.0075735013 | J13: ='Monthly P&L'!N89 -> 44435
A14: Cost of Operations
A15: Driver & Helper Labor | B15: =SUM('Monthly P&L'!B15:D15) -> 2265 | C15: =SUM('Monthly P&L'!E15:G15) -> 2289 | D15: =SUM('Monthly P&L'!H15:J15) -> 2578 | E15: =SUM('Monthly P&L'!K15:M15) -> 2605 | F15: =SUM(B15:E15) -> 9737 | G15: ='Monthly P&L'!N53 -> 9691 | H15: =G15-F15 -> -46 | I15: =IF(G15=0,0,H15/ABS(G15)) -> -0.0047466722 | J15: ='Monthly P&L'!N91 -> 8980
A16: Disposal & Tipping Fees | B16: =SUM('Monthly P&L'!B16:D16) -> 2217 | C16: =SUM('Monthly P&L'!E16:G16) -> 2198 | D16: =SUM('Monthly P&L'!H16:J16) -> 2303 | E16: =SUM('Monthly P&L'!K16:M16) -> 2455 | F16: =SUM(B16:E16) -> 9173 | G16: ='Monthly P&L'!N54 -> 8995 | H16: =G16-F16 -> -178 | I16: =IF(G16=0,0,H16/ABS(G16)) -> -0.019788772 | J16: ='Monthly P&L'!N92 -> 8465
A17: Fuel | B17: =SUM('Monthly P&L'!B17:D17) -> 929 | C17: =SUM('Monthly P&L'!E17:G17) -> 932 | D17: =SUM('Monthly P&L'!H17:J17) -> 957 | E17: =SUM('Monthly P&L'!K17:M17) -> 1015 | F17: =SUM(B17:E17) -> 3833 | G17: ='Monthly P&L'!N55 -> 3787 | H17: =G17-F17 -> -46 | I17: =IF(G17=0,0,H17/ABS(G17)) -> -0.012146818 | J17: ='Monthly P&L'!N93 -> 3645
A18: Fleet Maintenance & Repairs | B18: =SUM('Monthly P&L'!B18:D18) -> 1007 | C18: =SUM('Monthly P&L'!E18:G18) -> 1030 | D18: =SUM('Monthly P&L'!H18:J18) -> 1027 | E18: =SUM('Monthly P&L'!K18:M18) -> 1061 | F18: =SUM(B18:E18) -> 4125 | G18: ='Monthly P&L'!N56 -> 4032 | H18: =G18-F18 -> -93 | I18: =IF(G18=0,0,H18/ABS(G18)) -> -0.023065476 | J18: ='Monthly P&L'!N94 -> 4032
A19: Short-Term Truck Rental | B19: =SUM('Monthly P&L'!B19:D19) -> 0 | C19: =SUM('Monthly P&L'!E19:G19) -> 25 | D19: =SUM('Monthly P&L'!H19:J19) -> 160 | E19: =SUM('Monthly P&L'!K19:M19) -> 225 | F19: =SUM(B19:E19) -> 410 | G19: ='Monthly P&L'!N57 -> 0 | H19: =G19-F19 -> -410 | I19: =IF(G19=0,0,H19/ABS(G19)) -> 0 | J19: ='Monthly P&L'!N95 -> 0
A20: Container Repair & Delivery | B20: =SUM('Monthly P&L'!B20:D20) -> 136 | C20: =SUM('Monthly P&L'!E20:G20) -> 138 | D20: =SUM('Monthly P&L'!H20:J20) -> 155 | E20: =SUM('Monthly P&L'!K20:M20) -> 158 | F20: =SUM(B20:E20) -> 587 | G20: ='Monthly P&L'!N58 -> 585 | H20: =G20-F20 -> -2 | I20: =IF(G20=0,0,H20/ABS(G20)) -> -0.0034188034 | J20: ='Monthly P&L'!N96 -> 544
A21: Recycling Facility Operations | B21: =SUM('Monthly P&L'!B21:D21) -> 597 | C21: =SUM('Monthly P&L'!E21:G21) -> 597 | D21: =SUM('Monthly P&L'!H21:J21) -> 597 | E21: =SUM('Monthly P&L'!K21:M21) -> 597 | F21: =SUM(B21:E21) -> 2388 | G21: ='Monthly P&L'!N59 -> 2340 | H21: =G21-F21 -> -48 | I21: =IF(G21=0,0,H21/ABS(G21)) -> -0.020512821 | J21: ='Monthly P&L'!N97 -> 2340
A22: Insurance & Claims | B22: =SUM('Monthly P&L'!B22:D22) -> 320 | C22: =SUM('Monthly P&L'!E22:G22) -> 323 | D22: =SUM('Monthly P&L'!H22:J22) -> 358 | E22: =SUM('Monthly P&L'!K22:M22) -> 362 | F22: =SUM(B22:E22) -> 1363 | G22: ='Monthly P&L'!N60 -> 1360 | H22: =G22-F22 -> -3 | I22: =IF(G22=0,0,H22/ABS(G22)) -> -0.0022058824 | J22: ='Monthly P&L'!N98 -> 1268
A23: Total Cost of Operations | B23: =SUM('Monthly P&L'!B23:D23) -> 7471 | C23: =SUM('Monthly P&L'!E23:G23) -> 7532 | D23: =SUM('Monthly P&L'!H23:J23) -> 8135 | E23: =SUM('Monthly P&L'!K23:M23) -> 8478 | F23: =SUM(B23:E23) -> 31616 | G23: ='Monthly P&L'!N61 -> 30790 | H23: =G23-F23 -> -826 | I23: =IF(G23=0,0,H23/ABS(G23)) -> -0.026826892 | J23: ='Monthly P&L'!N99 -> 29274
A24: Gross Profit | B24: =SUM('Monthly P&L'!B24:D24) -> 3614 | C24: =SUM('Monthly P&L'!E24:G24) -> 3593 | D24: =SUM('Monthly P&L'!H24:J24) -> 4052 | E24: =SUM('Monthly P&L'!K24:M24) -> 3775 | F24: =SUM(B24:E24) -> 15034 | G24: ='Monthly P&L'!N62 -> 16216 | H24: =F24-G24 -> -1182 | I24: =IF(G24=0,0,H24/ABS(G24)) -> -0.072890972 | J24: ='Monthly P&L'!N100 -> 15161
A25: Selling, General & Administrative
A26: Sales & Customer Service | B26: =SUM('Monthly P&L'!B26:D26) -> 256 | C26: =SUM('Monthly P&L'!E26:G26) -> 259 | D26: =SUM('Monthly P&L'!H26:J26) -> 290 | E26: =SUM('Monthly P&L'!K26:M26) -> 293 | F26: =SUM(B26:E26) -> 1098 | G26: ='Monthly P&L'!N64 -> 1097 | H26: =G26-F26 -> -1 | I26: =IF(G26=0,0,H26/ABS(G26)) -> -0.00091157703 | J26: ='Monthly P&L'!N102 -> 1016
A27: G&A Salaries & Benefits | B27: =SUM('Monthly P&L'!B27:D27) -> 555 | C27: =SUM('Monthly P&L'!E27:G27) -> 555 | D27: =SUM('Monthly P&L'!H27:J27) -> 555 | E27: =SUM('Monthly P&L'!K27:M27) -> 555 | F27: =SUM(B27:E27) -> 2220 | G27: ='Monthly P&L'!N65 -> 2220 | H27: =G27-F27 -> 0 | I27: =IF(G27=0,0,H27/ABS(G27)) -> 0 | J27: ='Monthly P&L'!N103 -> 2136
A28: IT & Routing Software | B28: =SUM('Monthly P&L'!B28:D28) -> 102 | C28: =SUM('Monthly P&L'!E28:G28) -> 102 | D28: =SUM('Monthly P&L'!H28:J28) -> 102 | E28: =SUM('Monthly P&L'!K28:M28) -> 102 | F28: =SUM(B28:E28) -> 408 | G28: ='Monthly P&L'!N66 -> 408 | H28: =G28-F28 -> 0 | I28: =IF(G28=0,0,H28/ABS(G28)) -> 0 | J28: ='Monthly P&L'!N104 -> 396
A29: Professional Fees | B29: =SUM('Monthly P&L'!B29:D29) -> 81 | C29: =SUM('Monthly P&L'!E29:G29) -> 81 | D29: =SUM('Monthly P&L'!H29:J29) -> 81 | E29: =SUM('Monthly P&L'!K29:M29) -> 81 | F29: =SUM(B29:E29) -> 324 | G29: ='Monthly P&L'!N67 -> 324 | H29: =G29-F29 -> 0 | I29: =IF(G29=0,0,H29/ABS(G29)) -> 0 | J29: ='Monthly P&L'!N105 -> 312
A30: Rent & Facilities | B30: =SUM('Monthly P&L'!B30:D30) -> 93 | C30: =SUM('Monthly P&L'!E30:G30) -> 93 | D30: =SUM('Monthly P&L'!H30:J30) -> 93 | E30: =SUM('Monthly P&L'!K30:M30) -> 93 | F30: =SUM(B30:E30) -> 372 | G30: ='Monthly P&L'!N68 -> 372 | H30: =G30-F30 -> 0 | I30: =IF(G30=0,0,H30/ABS(G30)) -> 0 | J30: ='Monthly P&L'!N106 -> 360
A31: Sponsor Management Fee | B31: =SUM('Monthly P&L'!B31:D31) -> 150 | C31: =SUM('Monthly P&L'!E31:G31) -> 150 | D31: =SUM('Monthly P&L'!H31:J31) -> 150 | E31: =SUM('Monthly P&L'!K31:M31) -> 150 | F31: =SUM(B31:E31) -> 600 | G31: ='Monthly P&L'!N69 -> 600 | H31: =G31-F31 -> 0 | I31: =IF(G31=0,0,H31/ABS(G31)) -> 0 | J31: ='Monthly P&L'!N107 -> 576
A32: Other SG&A | B32: =SUM('Monthly P&L'!B32:D32) -> 75 | C32: =SUM('Monthly P&L'!E32:G32) -> 75 | D32: =SUM('Monthly P&L'!H32:J32) -> 75 | E32: =SUM('Monthly P&L'!K32:M32) -> 75 | F32: =SUM(B32:E32) -> 300 | G32: ='Monthly P&L'!N70 -> 300 | H32: =G32-F32 -> 0 | I32: =IF(G32=0,0,H32/ABS(G32)) -> 0 | J32: ='Monthly P&L'!N108 -> 288
A33: Total SG&A | B33: =SUM('Monthly P&L'!B33:D33) -> 1312 | C33: =SUM('Monthly P&L'!E33:G33) -> 1315 | D33: =SUM('Monthly P&L'!H33:J33) -> 1346 | E33: =SUM('Monthly P&L'!K33:M33) -> 1349 | F33: =SUM(B33:E33) -> 5322 | G33: ='Monthly P&L'!N71 -> 5321 | H33: =G33-F33 -> -1 | I33: =IF(G33=0,0,H33/ABS(G33)) -> -0.0001879346 | J33: ='Monthly P&L'!N109 -> 5084
A34: EBITDA | B34: =SUM('Monthly P&L'!B34:D34) -> 2302 | C34: =SUM('Monthly P&L'!E34:G34) -> 2278 | D34: =SUM('Monthly P&L'!H34:J34) -> 2706 | E34: =SUM('Monthly P&L'!K34:M34) -> 2426 | F34: =SUM(B34:E34) -> 9712 | G34: ='Monthly P&L'!N72 -> 10895 | H34: =F34-G34 -> -1183 | I34: =IF(G34=0,0,H34/ABS(G34)) -> -0.10858192 | J34: ='Monthly P&L'!N110 -> 10077
A35: EBITDA Margin | B35: =IF(B13=0,0,B34/B13) -> 0.20766802 | C35: =IF(C13=0,0,C34/C13) -> 0.20476404 | D35: =IF(D13=0,0,D34/D13) -> 0.22203988 | E35: =IF(E13=0,0,E34/E13) -> 0.19799233 | F35: =IF(F13=0,0,F34/F13) -> 0.20818864 | G35: =IF(G13=0,0,G34/G13) -> 0.23177892 | J35: =IF(J13=0,0,J34/J13) -> 0.22678069
A36: Below EBITDA
A37: Depreciation (Owned Fleet & Equipment) | B37: =SUM('Monthly P&L'!B36:D36) -> 801 | C37: =SUM('Monthly P&L'!E36:G36) -> 801 | D37: =SUM('Monthly P&L'!H36:J36) -> 801 | E37: =SUM('Monthly P&L'!K36:M36) -> 801 | F37: =SUM(B37:E37) -> 3204 | G37: ='Monthly P&L'!N74 -> 3204 | H37: =G37-F37 -> 0 | I37: =IF(G37=0,0,H37/ABS(G37)) -> 0 | J37: ='Monthly P&L'!N112 -> 3204
A38: Amortization of Finance Lease Assets | B38: =SUM('Monthly P&L'!B37:D37) -> 576 | C38: =SUM('Monthly P&L'!E37:G37) -> 576 | D38: =SUM('Monthly P&L'!H37:J37) -> 576 | E38: =SUM('Monthly P&L'!K37:M37) -> 576 | F38: =SUM(B38:E38) -> 2304 | G38: ='Monthly P&L'!N75 -> 2304 | H38: =G38-F38 -> 0 | I38: =IF(G38=0,0,H38/ABS(G38)) -> 0 | J38: ='Monthly P&L'!N113 -> 2076
A39: Amortization of Intangibles | B39: =SUM('Monthly P&L'!B38:D38) -> 399 | C39: =SUM('Monthly P&L'!E38:G38) -> 399 | D39: =SUM('Monthly P&L'!H38:J38) -> 399 | E39: =SUM('Monthly P&L'!K38:M38) -> 399 | F39: =SUM(B39:E39) -> 1596 | G39: ='Monthly P&L'!N76 -> 1596 | H39: =G39-F39 -> 0 | I39: =IF(G39=0,0,H39/ABS(G39)) -> 0 | J39: ='Monthly P&L'!N114 -> 1596
A40: Interest Expense | B40: =SUM('Monthly P&L'!B39:D39) -> 999 | C40: =SUM('Monthly P&L'!E39:G39) -> 999 | D40: =SUM('Monthly P&L'!H39:J39) -> 999 | E40: =SUM('Monthly P&L'!K39:M39) -> 999 | F40: =SUM(B40:E40) -> 3996 | G40: ='Monthly P&L'!N77 -> 3996 | H40: =G40-F40 -> 0 | I40: =IF(G40=0,0,H40/ABS(G40)) -> 0 | J40: ='Monthly P&L'!N115 -> 3840
A41: Income Taxes | B41: =SUM('Monthly P&L'!B40:D40) -> 24 | C41: =SUM('Monthly P&L'!E40:G40) -> 24 | D41: =SUM('Monthly P&L'!H40:J40) -> 24 | E41: =SUM('Monthly P&L'!K40:M40) -> 24 | F41: =SUM(B41:E41) -> 96 | G41: ='Monthly P&L'!N78 -> 96 | H41: =G41-F41 -> 0 | I41: =IF(G41=0,0,H41/ABS(G41)) -> 0 | J41: ='Monthly P&L'!N116 -> 96
...

Sheet Monthly P&L
A1: HARROW RIDGE ENVIRONMENTAL SERVICES
A2: Monthly Income Statement: Actual, Budget and Prior Year (fiscal months)
A3: $ in thousands
A4: Accrual basis, US GAAP, unaudited management accounts. Finance leases recognized under ASC 842. Synthetic test data. Fictional company; not based on any real business.
A6: ACTUAL FY2026 | B6: Oct-25 | C6: Nov-25 | D6: Dec-25 | E6: Jan-26 | F6: Feb-26 | G6: Mar-26 | H6: Apr-26 | I6: May-26 | J6: Jun-26 | K6: Jul-26 | L6: Aug-26 | M6: Sep-26 | N6: Full Year
A7: Revenue
A8: Commercial Front-Load Collection | B8: 2145 | C8: 2113 | D8: 2097 | E8: 2167 | F8: 2169 | G8: 2235 | H8: 2262 | I8: 2299 | J8: 2347 | K8: 2335 | L8: 2329 | M8: 2334 | N8: =SUM(B8:M8) -> 26832
A9: Roll-Off & Industrial Collection | B9: 1011 | C9: 918 | D9: 859 | E9: 830 | F9: 852 | G9: 991 | H9: 1091 | I9: 1159 | J9: 1195 | K9: 1172 | L9: 1174 | M9: 1119 | N9: =SUM(B9:M9) -> 12371
A10: Fuel Surcharge & Environmental Fees | B10: 268 | C10: 258 | D10: 248 | E10: 258 | F10: 272 | G10: 298 | H10: 298 | I10: 294 | J10: 292 | K10: 296 | L10: 308 | M10: 314 | N10: =SUM(B10:M10) -> 3404
A11: Recycling Commodity Sales | B11: 283 | C11: 276 | D11: 264 | E11: 250 | F11: 235 | G11: 223 | H11: 211 | I11: 202 | J11: 192 | K11: 182 | L11: 175 | M11: 170 | N11: =SUM(B11:M11) -> 2663
A12: Processing & Other Revenue | B12: 115 | C12: 115 | D12: 115 | E12: 115 | F12: 115 | G12: 115 | H12: 115 | I12: 115 | J12: 115 | K12: 115 | L12: 115 | M12: 115 | N12: =SUM(B12:M12) -> 1380
A13: Total Revenue | B13: =SUM(B8:B12) -> 3822 | C13: =SUM(C8:C12) -> 3680 | D13: =SUM(D8:D12) -> 3583 | E13: =SUM(E8:E12) -> 3620 | F13: =SUM(F8:F12) -> 3643 | G13: =SUM(G8:G12) -> 3862 | H13: =SUM(H8:H12) -> 3977 | I13: =SUM(I8:I12) -> 4069 | ... M13: =SUM(M8:M12) -> 4052 | N13: =SUM(B13:M13) -> 46650
A14: Cost of Operations
A15: Driver & Helper Labor | B15: 782 | C15: 751 | D15: 732 | E15: 742 | F15: 748 | G15: 799 | H15: 835 | I15: 861 | J15: 882 | K15: 873 | L15: 872 | M15: 860 | N15: =SUM(B15:M15) -> 9737
A16: Disposal & Tipping Fees | B16: 750 | C16: 737 | D16: 730 | E16: 724 | F16: 725 | G16: 749 | H16: 754 | I16: 770 | J16: 779 | K16: 820 | L16: 821 | M16: 814 | N16: =SUM(B16:M16) -> 9173
A17: Fuel | B17: 310 | C17: 308 | D17: 311 | E17: 313 | F17: 308 | G17: 311 | H17: 309 | I17: 319 | J17: 329 | K17: 334 | L17: 340 | M17: 341 | N17: =SUM(B17:M17) -> 3833
A18: Fleet Maintenance & Repairs | B18: 331 | C18: 336 | D18: 340 | E18: 339 | F18: 343 | G18: 348 | H18: 339 | I18: 342 | J18: 346 | K18: 350 | L18: 354 | M18: 357 | N18: =SUM(B18:M18) -> 4125
A19: Short-Term Truck Rental | B19: 0 | C19: 0 | D19: 0 | E19: 0 | F19: 0 | G19: 25 | H19: 40 | I19: 55 | J19: 65 | K19: 70 | L19: 75 | M19: 80 | N19: =SUM(B19:M19) -> 410
A20: Container Repair & Delivery | B20: 47 | C20: 45 | D20: 44 | E20: 45 | F20: 45 | G20: 48 | H20: 50 | I20: 52 | J20: 53 | K20: 53 | L20: 53 | M20: 52 | N20: =SUM(B20:M20) -> 587
A21: Recycling Facility Operations | B21: 199 | C21: 199 | D21: 199 | E21: 199 | F21: 199 | G21: 199 | H21: 199 | I21: 199 | J21: 199 | K21: 199 | L21: 199 | M21: 199 | N21: =SUM(B21:M21) -> 2388
A22: Insurance & Claims | B22: 110 | C22: 106 | D22: 104 | E22: 105 | F22: 106 | G22: 112 | H22: 116 | I22: 120 | J22: 122 | K22: 121 | L22: 121 | M22: 120 | N22: =SUM(B22:M22) -> 1363
A23: Total Cost of Operations | B23: =SUM(B15:B22) -> 2529 | C23: =SUM(C15:C22) -> 2482 | D23: =SUM(D15:D22) -> 2460 | E23: =SUM(E15:E22) -> 2467 | F23: =SUM(F15:F22) -> 2474 | G23: =SUM(G15:G22) -> 2591 | H23: =SUM(H15:H22) -> 2642 | I23: =SUM(I15:I22) -> 2718 | ... M23: =SUM(M15:M22) -> 2823 | N23: =SUM(B23:M23) -> 31616
A24: Gross Profit | B24: =B13-B23 -> 1293 | C24: =C13-C23 -> 1198 | D24: =D13-D23 -> 1123 | E24: =E13-E23 -> 1153 | F24: =F13-F23 -> 1169 | G24: =G13-G23 -> 1271 | H24: =H13-H23 -> 1335 | I24: =I13-I23 -> 1351 | ... M24: =M13-M23 -> 1229 | N24: =SUM(B24:M24) -> 15034
A25: Selling, General & Administrative
A26: Sales & Customer Service | B26: 88 | C26: 85 | D26: 83 | E26: 84 | F26: 85 | G26: 90 | H26: 94 | I26: 97 | J26: 99 | K26: 98 | L26: 98 | M26: 97 | N26: =SUM(B26:M26) -> 1098
A27: G&A Salaries & Benefits | B27: 185 | C27: 185 | D27: 185 | E27: 185 | F27: 185 | G27: 185 | H27: 185 | I27: 185 | J27: 185 | K27: 185 | L27: 185 | M27: 185 | N27: =SUM(B27:M27) -> 2220
A28: IT & Routing Software | B28: 34 | C28: 34 | D28: 34 | E28: 34 | F28: 34 | G28: 34 | H28: 34 | I28: 34 | J28: 34 | K28: 34 | L28: 34 | M28: 34 | N28: =SUM(B28:M28) -> 408
A29: Professional Fees | B29: 27 | C29: 27 | D29: 27 | E29: 27 | F29: 27 | G29: 27 | H29: 27 | I29: 27 | J29: 27 | K29: 27 | L29: 27 | M29: 27 | N29: =SUM(B29:M29) -> 324
A30: Rent & Facilities | B30: 31 | C30: 31 | D30: 31 | E30: 31 | F30: 31 | G30: 31 | H30: 31 | I30: 31 | J30: 31 | K30: 31 | L30: 31 | M30: 31 | N30: =SUM(B30:M30) -> 372
A31: Sponsor Management Fee | B31: 50 | C31: 50 | D31: 50 | E31: 50 | F31: 50 | G31: 50 | H31: 50 | I31: 50 | J31: 50 | K31: 50 | L31: 50 | M31: 50 | N31: =SUM(B31:M31) -> 600
A32: Other SG&A | B32: 25 | C32: 25 | D32: 25 | E32: 25 | F32: 25 | G32: 25 | H32: 25 | I32: 25 | J32: 25 | K32: 25 | L32: 25 | M32: 25 | N32: =SUM(B32:M32) -> 300
A33: Total SG&A | B33: =SUM(B26:B32) -> 440 | C33: =SUM(C26:C32) -> 437 | D33: =SUM(D26:D32) -> 435 | E33: =SUM(E26:E32) -> 436 | F33: =SUM(F26:F32) -> 437 | G33: =SUM(G26:G32) -> 442 | H33: =SUM(H26:H32) -> 446 | I33: =SUM(I26:I32) -> 449 | ... M33: =SUM(M26:M32) -> 449 | N33: =SUM(B33:M33) -> 5322
A34: EBITDA | B34: =B24-B33 -> 853 | C34: =C24-C33 -> 761 | D34: =D24-D33 -> 688 | E34: =E24-E33 -> 717 | F34: =F24-F33 -> 732 | G34: =G24-G33 -> 829 | H34: =H24-H33 -> 889 | I34: =I24-I33 -> 902 | ... M34: =M24-M33 -> 780 | N34: =SUM(B34:M34) -> 9712
A35: EBITDA Margin | B35: =IF(B13=0,0,B34/B13) -> 0.22318158 | C35: =IF(C13=0,0,C34/C13) -> 0.20679348 | D35: =IF(D13=0,0,D34/D13) -> 0.19201786 | E35: =IF(E13=0,0,E34/E13) -> 0.1980663 | F35: =IF(F13=0,0,F34/F13) -> 0.2009333 | G35: =IF(G13=0,0,G34/G13) -> 0.21465562 | H35: =IF(H13=0,0,H34/H13) -> 0.22353533 | I35: =IF(I13=0,0,I34/I13) -> 0.22167609 | ... N35: =IF(N13=0,0,N34/N13) -> 0.20818864
A36: Depreciation (Owned Fleet & Equipment) | B36: 267 | C36: 267 | D36: 267 | E36: 267 | F36: 267 | G36: 267 | H36: 267 | I36: 267 | J36: 267 | K36: 267 | L36: 267 | M36: 267 | N36: =SUM(B36:M36) -> 3204
A37: Amortization of Finance Lease Assets | B37: 192 | C37: 192 | D37: 192 | E37: 192 | F37: 192 | G37: 192 | H37: 192 | I37: 192 | J37: 192 | K37: 192 | L37: 192 | M37: 192 | N37: =SUM(B37:M37) -> 2304
A38: Amortization of Intangibles | B38: 133 | C38: 133 | D38: 133 | E38: 133 | F38: 133 | G38: 133 | H38: 133 | I38: 133 | J38: 133 | K38: 133 | L38: 133 | M38: 133 | N38: =SUM(B38:M38) -> 1596
A39: Interest Expense | B39: 333 | C39: 333 | D39: 333 | E39: 333 | F39: 333 | G39: 333 | H39: 333 | I39: 333 | J39: 333 | K39: 333 | L39: 333 | M39: 333 | N39: =SUM(B39:M39) -> 3996
A40: Income Taxes | B40: 8 | C40: 8 | D40: 8 | E40: 8 | F40: 8 | G40: 8 | H40: 8 | I40: 8 | J40: 8 | K40: 8 | L40: 8 | M40: 8 | N40: =SUM(B40:M40) -> 96
A41: Net Income (Loss) | B41: =B34-SUM(B36:B40) -> -80 | C41: =C34-SUM(C36:C40) -> -172 | D41: =D34-SUM(D36:D40) -> -245 | E41: =E34-SUM(E36:E40) -> -216 | F41: =F34-SUM(F36:F40) -> -201 | G41: =G34-SUM(G36:G40) -> -104 | H41: =H34-SUM(H36:H40) -> -44 | I41: =I34-SUM(I36:I40) -> -31 | ... M41: =M34-SUM(M36:M40) -> -153 | N41: =SUM(B41:M41) -> -1484
...

Sheet Cash Flow & Capex
A1: HARROW RIDGE ENVIRONMENTAL SERVICES
A2: Cash Flow and Capital Expenditures, Fiscal Year 2026 (quarterly)
A3: $ in thousands
A4: Accrual basis, US GAAP, unaudited management accounts. Finance leases recognized under ASC 842. Synthetic test data. Fictional company; not based on any real business.
B6: Q1 FY26 | C6: Q2 FY26 | D6: Q3 FY26 | E6: Q4 FY26 | F6: FY2026 | G6: Notes
A7: Operating activities
A8: EBITDA | B8: ='P&L Summary'!B34 -> 2302 | C8: ='P&L Summary'!C34 -> 2278 | D8: ='P&L Summary'!D34 -> 2706 | E8: ='P&L Summary'!E34 -> 2426 | F8: =SUM(B8:E8) -> 9712
A9: Cash interest paid (term loan, revolver and finance leases) | B9: -999 | C9: -999 | D9: -999 | E9: -999 | F9: =SUM(B9:E9) -> -3996
A10: Cash taxes paid | B10: -24 | C10: -24 | D10: -24 | E10: -24 | F10: =SUM(B10:E10) -> -96
A11: Change in net working capital | B11: 120 | C11: 160 | D11: -380 | E11: -220 | F11: =SUM(B11:E11) -> -320 | G11: Receivables, prepaid, payables and accruals; see Balance Sheet
A12: Cash flow from operations | B12: =SUM(B8:B11) -> 1399 | C12: =SUM(C8:C11) -> 1415 | D12: =SUM(D8:D11) -> 1303 | E12: =SUM(E8:E11) -> 1183 | F12: =SUM(B12:E12) -> 5300
A14: Investing activities
A15: Maintenance capital expenditures (cash) | B15: -500 | C15: -450 | D15: -600 | E15: -550 | F15: =SUM(B15:E15) -> -2100 | G15: Owned trucks, containers and equipment
A16: Growth capital expenditures (cash) | B16: -250 | C16: -200 | D16: -250 | E16: -200 | F16: =SUM(B16:E16) -> -900 | G16: Containers and equipment for new contracts
A17: Cash flow from investing | B17: =B15+B16 -> -750 | C17: =C15+C16 -> -650 | D17: =D15+D16 -> -850 | E17: =E15+E16 -> -750 | F17: =SUM(B17:E17) -> -3000
A19: Financing activities
A20: Finance lease principal payments | B20: -650 | C20: -650 | D20: -650 | E20: -650 | F20: =SUM(B20:E20) -> -2600
A21: Term loan amortization | B21: -100 | C21: -100 | D21: -100 | E21: -100 | F21: =SUM(B21:E21) -> -400
A22: Revolver draws / (repayments), net | B22: 0 | C22: 0 | D22: 0 | E22: 0 | F22: =SUM(B22:E22) -> 0
A23: Cash flow from financing | B23: =SUM(B20:B22) -> -750 | C23: =SUM(C20:C22) -> -750 | D23: =SUM(D20:D22) -> -750 | E23: =SUM(E20:E22) -> -750 | F23: =SUM(B23:E23) -> -3000
A25: Net change in cash | B25: =B12+B17+B23 -> -101 | C25: =C12+C17+C23 -> 15 | D25: =D12+D17+D23 -> -297 | E25: =E12+E17+E23 -> -317 | F25: =SUM(B25:E25) -> -700
A26: Beginning cash | B26: 3200 | C26: 3099 | D26: 3114 | E26: 2817 | F26: =B26 -> 3200
A27: Ending cash | B27: =B26+B25 -> 3099 | C27: =C26+C25 -> 3114 | D27: =D26+D25 -> 2817 | E27: =E26+E25 -> 2500 | F27: =E27 -> 2500
A29: Supplemental: non-cash investing
A30: Collection trucks acquired under new finance leases | B30: 900 | C30: 1000 | D30: 1200 | E30: 1200 | F30: =SUM(B30:E30) -> 4300 | G30: Non-cash; added to finance lease assets and liabilities
A32: Management free cash flow
A33: EBITDA | B33: =B8 -> 2302 | C33: =C8 -> 2278 | D33: =D8 -> 2706 | E33: =E8 -> 2426 | F33: =SUM(B33:E33) -> 9712
A34: Less: capital expenditures (cash) | B34: =B17 -> -750 | C34: =C17 -> -650 | D34: =D17 -> -850 | E34: =E17 -> -750 | F34: =SUM(B34:E34) -> -3000
A35: Free cash flow (management definition) | B35: =B33+B34 -> 1552 | C35: =C33+C34 -> 1628 | D35: =D33+D34 -> 1856 | E35: =E33+E34 -> 1676 | F35: =SUM(B35:E35) -> 6712
A36: Free cash flow conversion (FCF / EBITDA) | B36: =IF(B33=0,0,B35/B33) -> 0.67419635 | C36: =IF(C33=0,0,C35/C33) -> 0.71466198 | D36: =IF(D33=0,0,D35/D33) -> 0.68588322 | E36: =IF(E33=0,0,E35/E33) -> 0.69084913 | F36: =IF(F33=0,0,F35/F33) -> 0.69110379

Sheet Balance Sheet
A1: HARROW RIDGE ENVIRONMENTAL SERVICES
A2: Balance Sheet, Fiscal Quarter-Ends
A3: $ in thousands
A4: Accrual basis, US GAAP, unaudited management accounts. Finance leases recognized under ASC 842. Synthetic test data. Fictional company; not based on any real business.
B6: Sep 30, 2025 | C6: Dec 31, 2025 | D6: Mar 31, 2026 | E6: Jun 30, 2026 | F6: Sep 30, 2026
A7: Assets
A8: Cash | B8: 3200 | C8: 3099 | D8: 3114 | E8: 2817 | F8: 2500
A9: Accounts receivable, net | B9: 4700 | C9: 4520 | D9: 4380 | E9: 4960 | F9: 5240
A10: Prepaid expenses & other | B10: 900 | C10: 920 | D10: 940 | E10: 930 | F10: 950
A11: Property & equipment, net (owned) | B11: 24000 | C11: 23949 | D11: 23798 | E11: 23847 | F11: 23796
A12: Finance lease right-of-use assets, net | B12: 9500 | C12: 9824 | D12: 10248 | E12: 10872 | F12: 11496
A13: Goodwill & intangible assets, net | B13: 38000 | C13: 37601 | D13: 37202 | E13: 36803 | F13: 36404
A14: Total assets | B14: =SUM(B8:B13) -> 80300 | C14: =SUM(C8:C13) -> 79913 | D14: =SUM(D8:D13) -> 79682 | E14: =SUM(E8:E13) -> 80229 | F14: =SUM(F8:F13) -> 80386
A16: Liabilities & equity
A17: Accounts payable | B17: 2400 | C17: 2380 | D17: 2350 | E17: 2480 | F17: 2510
A18: Accrued liabilities | B18: 1900 | C18: 1880 | D18: 1950 | E18: 2010 | F18: 2060
A19: Revolving credit facility | B19: 1000 | C19: 1000 | D19: 1000 | E19: 1000 | F19: 1000
A20: Term loan | B20: 40000 | C20: 39900 | D20: 39800 | E20: 39700 | F20: 39600
A21: Finance lease liabilities | B21: 9800 | C21: 10050 | D21: 10400 | E21: 10950 | F21: 11500
A22: Total liabilities | B22: =SUM(B17:B21) -> 55100 | C22: =SUM(C17:C21) -> 55210 | D22: =SUM(D17:D21) -> 55500 | E22: =SUM(E17:E21) -> 56140 | F22: =SUM(F17:F21) -> 56670
A23: Members' equity | B23: 25200 | C23: 24703 | D23: 24182 | E23: 24089 | F23: 23716
A24: Total liabilities & equity | B24: =B22+B23 -> 80300 | C24: =C22+C23 -> 79913 | D24: =D22+D23 -> 79682 | E24: =E22+E23 -> 80229 | F24: =F22+F23 -> 80386
A26: Total debt incl. finance leases | B26: =B19+B20+B21 -> 50800 | C26: =C19+C20+C21 -> 50950 | D26: =D19+D20+D21 -> 51200 | E26: =E19+E20+E21 -> 51650 | F26: =F19+F20+F21 -> 52100

Sheet Segment Results
A1: HARROW RIDGE ENVIRONMENTAL SERVICES
A2: Segment Results, Fiscal Year 2026
A3: $ in thousands
A4: Accrual basis, US GAAP, unaudited management accounts. Finance leases recognized under ASC 842. Synthetic test data. Fictional company; not based on any real business.
B6: North | C6: South | D6: East | E6: Recycling | F6: Corporate & Other | G6: Consolidated | H6: Notes
A7: FY2026 Actual
A8: Revenue | B8: 17845 | C8: 13042 | D8: 11722 | E8: 3144 | F8: 897 | G8: =SUM(B8:F8) -> 46650 | H8: Corporate & other: container rental and miscellaneous fees
A9: Labor | B9: 3940 | C9: 3153 | D9: 2642 | E9: 0 | F9: 0 | G9: =SUM(B9:F9) -> 9735
A10: Disposal | B10: 3514 | C10: 2857 | D10: 2800 | E10: 0 | F10: 0 | G10: =SUM(B10:F10) -> 9171
A11: Fuel | B11: 1503 | C11: 1260 | D11: 1069 | E11: 0 | F11: 0 | G11: =SUM(B11:F11) -> 3832
A12: Fleet maintenance & rental | B12: 1288 | C12: 1990 | D12: 912 | E12: 346 | F12: 0 | G12: =SUM(B12:F12) -> 4536
A13: Facility operations | B13: 0 | C13: 0 | D13: 0 | E13: 2388 | F13: 0 | G13: =SUM(B13:F13) -> 2388
A14: Containers, insurance & sales | B14: 1231 | C14: 900 | D14: 809 | E14: 108 | F14: 4 | G14: =SUM(B14:F14) -> 3052
A15: Segment operating costs | B15: =SUM(B9:B14) -> 11476 | C15: =SUM(C9:C14) -> 10160 | D15: =SUM(D9:D14) -> 8232 | E15: =SUM(E9:E14) -> 2842 | F15: =SUM(F9:F14) -> 4 | G15: =SUM(B15:F15) -> 32714
A16: Corporate SG&A | B16: 0 | C16: 0 | D16: 0 | E16: 0 | F16: 4224 | G16: =SUM(B16:F16) -> 4224
A17: Segment EBITDA | B17: =B8-B15-B16 -> 6369 | C17: =C8-C15-C16 -> 2882 | D17: =D8-D15-D16 -> 3490 | E17: =E8-E15-E16 -> 302 | F17: =F8-F15-F16 -> -3331 | G17: =SUM(B17:F17) -> 9712
A18: EBITDA margin | B18: =IF(B8=0,0,B17/B8) -> 0.3569067 | C18: =IF(C8=0,0,C17/C8) -> 0.22097838 | D18: =IF(D8=0,0,D17/D8) -> 0.29773076 | E18: =IF(E8=0,0,E17/E8) -> 0.09605598 | F18: =IF(F8=0,0,F17/F8) -> -3.7134894 | G18: =IF(G8=0,0,G17/G8) -> 0.20818864
A20: FY2026 Budget
A21: Revenue (budget) | B21: 17358 | C21: 13255 | D21: 11842 | E21: 3648
A22: Segment operating costs (budget) | B22: 11227 | C22: 9725 | D22: 8149 | E22: 2794
A23: Segment EBITDA before corporate (budget) | B23: =B21-B22 -> 6131 | C23: =C21-C22 -> 3530 | D23: =D21-D22 -> 3693 | E23: =E21-E22 -> 854
A24: Segment EBITDA before corporate (actual) | B24: =B8-B15 -> 6369 | C24: =C8-C15 -> 2882 | D24: =D8-D15 -> 3490 | E24: =E8-E15 -> 302
A25: Variance to budget | B25: =B24-B23 -> 238 | C25: =C24-C23 -> -648 | D25: =D24-D23 -> -203 | E25: =E24-E23 -> -552
A27: Q4 FY2026 (Jul-Sep) Actual
A28: Q4 revenue | B28: 4830 | C28: 3446 | D28: 3107 | E28: 648
A29: Q4 segment operating costs | B29: 3042 | C29: 2786 | D29: 2232 | E29: 710
A30: Q4 EBITDA margin before corporate | B30: =IF(B28=0,0,(B28-B29)/B28) -> 0.37018634 | C30: =IF(C28=0,0,(C28-C29)/C28) -> 0.19152641 | D30: =IF(D28=0,0,(D28-D29)/D28) -> 0.28162214 | E30: =IF(E28=0,0,(E28-E29)/E28) -> -0.095679012
A31: Q3 revenue | B31: 4743 | C31: 3404 | D31: 3089 | E31: 725
A32: Q3 segment operating costs | B32: 2975 | C32: 2651 | D32: 2088 | E32: 710
A33: Q3 EBITDA margin before corporate | B33: =IF(B31=0,0,(B31-B32)/B31) -> 0.37275986 | C33: =IF(C31=0,0,(C31-C32)/C31) -> 0.22121034 | D33: =IF(D31=0,0,(D31-D32)/D31) -> 0.32405309 | E33: =IF(E31=0,0,(E31-E32)/E31) -> 0.020689655
A35: FY2026 capital deployed by segment (cash capex + new finance leases)
A36: Capital deployed | B36: 3250 | C36: 650 | D36: 2700 | E36: 300 | F36: 400 | G36: =SUM(B36:F36) -> 7300 | H36: Totals to cash capex plus new finance leases on Cash Flow & Capex

Sheet Operating KPIs
A1: HARROW RIDGE ENVIRONMENTAL SERVICES
A2: Operating KPIs by Territory, FY2026 by Quarter
A3: Units as stated in each row
A4: Accrual basis, US GAAP, unaudited management accounts. Finance leases recognized under ASC 842. Synthetic test data. Fictional company; not based on any real business.
A6: KPI | B6: Unit | C6: North Q1 | D6: North Q2 | E6: North Q3 | F6: North Q4 | G6: South Q1 | H6: South Q2 | I6: South Q3 | J6: South Q4 | K6: East Q1 | L6: East Q2 | M6: East Q3 | N6: East Q4
A7: Collection productivity
A8: Collection revenue (excl. fuel surcharge) | B8: $000 | C8: 3748 | D8: 3860 | E8: 4370 | F8: 4440 | G8: 2855 | H8: 2841 | I8: 3136 | J8: 3168 | K8: 2540 | L8: 2543 | M8: 2846 | N8: 2856
A9: Active routes | B9: # | C9: 26 | D9: 26 | E9: 27 | F9: 27 | G9: 22 | H9: 22 | I9: 22 | J9: 22 | K9: 18 | L9: 18 | M9: 18 | N9: 18
A10: Route-days operated | B10: # | C10: =C9*65 -> 1690 | D10: =D9*65 -> 1690 | E10: =E9*65 -> 1755 | F10: =F9*65 -> 1755 | G10: =G9*65 -> 1430 | H10: =H9*65 -> 1430 | I10: =I9*65 -> 1430 | J10: =J9*65 -> 1430 | ... N10: =N9*65 -> 1170
A11: Revenue per route-day | B11: $ | C11: =IF(C10=0,0,C8*1000/C10) -> 2217.7515 | D11: =IF(D10=0,0,D8*1000/D10) -> 2284.0237 | E11: =IF(E10=0,0,E8*1000/E10) -> 2490.0285 | F11: =IF(F10=0,0,F8*1000/F10) -> 2529.9145 | G11: =IF(G10=0,0,G8*1000/G10) -> 1996.5035 | H11: =IF(H10=0,0,H8*1000/H10) -> 1986.7133 | I11: =IF(I10=0,0,I8*1000/I10) -> 2193.007 | J11: =IF(J10=0,0,J8*1000/J10) -> 2215.3846 | ... N11: =IF(N10=0,0,N8*1000/N10) -> 2441.0256
A12: Tons collected | B12: tons | C12: 18066 | D12: 18036 | E12: 19127 | F12: 19539 | G12: 14455 | H12: 14259 | I12: 14721 | J12: 14866 | K12: 12685 | L12: 12513 | M12: 13115 | N12: 13244
A13: Disposal and fuel
A14: Disposal cost | B14: $000 | C14: 849 | D14: 848 | E14: 899 | F14: 918 | G14: 708 | H14: 699 | I14: 721 | J14: 728 | K14: 660 | L14: 651 | M14: 682 | N14: 808
A15: Disposal cost per ton | B15: $ | C15: =IF(C12=0,0,C14*1000/C12) -> 46.994354 | D15: =IF(D12=0,0,D14*1000/D12) -> 47.017077 | E15: =IF(E12=0,0,E14*1000/E12) -> 47.001621 | F15: =IF(F12=0,0,F14*1000/F12) -> 46.982957 | G15: =IF(G12=0,0,G14*1000/G12) -> 48.979592 | H15: =IF(H12=0,0,H14*1000/H12) -> 49.021671 | I15: =IF(I12=0,0,I14*1000/I12) -> 48.977651 | J15: =IF(J12=0,0,J14*1000/J12) -> 48.970806 | ... N15: =IF(N12=0,0,N14*1000/N12) -> 61.008759
A16: Fuel cost | B16: $000 | C16: 360 | D16: 363 | E16: 378 | F16: 403 | G16: 309 | H16: 309 | I16: 312 | J16: 330 | K16: 261 | L16: 260 | M16: 267 | N16: 282
A17: Fuel surcharge revenue | B17: $000 | C17: 317 | D17: 346 | E17: 373 | F17: 390 | G17: 242 | H17: 255 | I17: 268 | J17: 278 | K17: 215 | L17: 228 | M17: 243 | N17: 251
A18: Fuel cost recovery (surcharge / fuel cost) | B18: % | C18: =IF(C16=0,0,C17/C16) -> 0.88055556 | D18: =IF(D16=0,0,D17/D16) -> 0.95316804 | E18: =IF(E16=0,0,E17/E16) -> 0.98677249 | F18: =IF(F16=0,0,F17/F16) -> 0.96774194 | G18: =IF(G16=0,0,G17/G16) -> 0.78317152 | H18: =IF(H16=0,0,H17/H16) -> 0.82524272 | I18: =IF(I16=0,0,I17/I16) -> 0.85897436 | J18: =IF(J16=0,0,J17/J16) -> 0.84242424 | ... N18: =IF(N16=0,0,N17/N16) -> 0.89007092
A19: Fleet
A20: Trucks in service (quarter-end) | B20: # | C20: 58 | D20: 58 | E20: 58 | F20: 58 | G20: 51 | H20: 48 | I20: 42 | J20: 42 | K20: 40 | L20: 40 | M20: 40 | N20: 40
A21: Truck downtime (% of scheduled days) | B21: % | C21: 0.051 | D21: 0.049 | E21: 0.048 | F21: 0.047 | G21: 0.082 | H21: 0.096 | I21: 0.118 | J21: 0.141 | K21: 0.055 | L21: 0.054 | M21: 0.057 | N21: 0.056
A22: Fleet maintenance cost per truck in service, monthly avg | B22: $ | C22: 1850 | D22: 1850 | E22: 1850 | F22: 1850 | G22: 2390 | H22: 2660 | I22: 2930 | J22: 3200 | K22: 1900 | L22: 1900 | M22: 1900 | N22: 1900
A23: Short-term truck rental | B23: $000 | C23: 0 | D23: 0 | E23: 0 | F23: 0 | G23: 0 | H23: 25 | I23: 160 | J23: 225 | K23: 0 | L23: 0 | M23: 0 | N23: 0
A24: Average fleet age (quarter-end) | B24: years | C24: 6.1 | D24: 5.9 | E24: 5.8 | F24: 5.6 | G24: 8.7 | H24: 9 | I24: 9.2 | J24: 9.4 | K24: 6.4 | L24: 6.3 | M24: 6.1 | N24: 6
A25: Customers
A26: Customers (quarter-end) | B26: # | C26: 2152 | D26: 2175 | E26: 2198 | F26: 2224 | G26: 1714 | H26: 1705 | I26: 1693 | J26: 1679 | K26: 1494 | L26: 1499 | M26: 1502 | N26: 1506
A27: Customer churn, annualized | B27: % | C27: 0.062 | D27: 0.06 | E27: 0.058 | F27: 0.057 | G27: 0.071 | H27: 0.079 | I27: 0.088 | J27: 0.097 | K27: 0.065 | L27: 0.066 | M27: 0.064 | N27: 0.066
A28: Average price change on contracts renewed in quarter | B28: % | C28: 0.048 | D28: 0.052 | E28: 0.05 | F28: 0.049 | G28: 0.031 | H28: 0.029 | I28: 0.026 | J28: 0.024 | K28: 0.03 | L28: 0.029 | M28: 0.03 | N28: 0.028
A30: Recycling facility (single site)
A31: Tons processed | B31: tons | C31: 7200 | D31: 7200 | E31: 7200 | F31: 7200
A32: Average commodity price received | B32: $/ton | C32: 114.33 | D32: 98.33 | E32: 84 | F32: 73.33
A33: Residue rate (landfilled share of inbound) | B33: % | C33: 0.142 | D33: 0.145 | E33: 0.151 | F33: 0.149
A34: Recycling KPIs shown in columns C to F (Q1 to Q4).
A36: Company productivity
A37: Trucks in service, company (Sep 30, 2026) | C37: =F20+J20+N20+12 -> 152 | D37: Territory trucks in service plus 12 recycling-site units
A38: Revenue per truck in service, FY2026 | C38: =IF(C37=0,0,'P&L Summary'!F13/C37) -> 306.90789 | D38: $000 per truck

Sheet Fleet Register
A1: HARROW RIDGE ENVIRONMENTAL SERVICES
A2: Fleet Register Summary, September 30, 2026
A3: Unit counts
A4: Accrual basis, US GAAP, unaudited management accounts. Finance leases recognized under ASC 842. Synthetic test data. Fictional company; not based on any real business.
A6: Territory / site | B6: Front-load | C6: Roll-off | D6: Rear-load & other | E6: Total units | F6: In service | G6: Out of service | H6: Finance-leased | I6: Owned
A7: North | B7: 32 | C7: 16 | D7: 10 | E7: =SUM(B7:D7) -> 58 | F7: =E7-G7 -> 58 | G7: 0 | H7: 21 | I7: =E7-H7 -> 37
A8: South | B8: 30 | C8: 14 | D8: 10 | E8: =SUM(B8:D8) -> 54 | F8: =E8-G8 -> 42 | G8: 12 | H8: 9 | I8: =E8-H8 -> 45
A9: East | B9: 22 | C9: 11 | D9: 7 | E9: =SUM(B9:D9) -> 40 | F9: =E9-G9 -> 40 | G9: 0 | H9: 16 | I9: =E9-H9 -> 24
A10: Recycling site | B10: 0 | C10: 0 | D10: 12 | E10: =SUM(B10:D10) -> 12 | F10: =E10-G10 -> 12 | G10: 0 | H10: 2 | I10: =E10-H10 -> 10
A11: Total fleet | B11: =SUM(B7:B10) -> 84 | C11: =SUM(C7:C10) -> 41 | D11: =SUM(D7:D10) -> 39 | E11: =SUM(E7:E10) -> 164 | F11: =SUM(F7:F10) -> 152 | G11: =SUM(G7:G10) -> 12 | H11: =SUM(H7:H10) -> 48 | I11: =SUM(I7:I10) -> 116
A13: Out-of-service detail (South)
A14: 7 front-load units awaiting engine or transmission rebuild (average 11 weeks out of service)
A15: 5 roll-off units retired from routes, pending disposal decision; still on the depreciation schedule
A16: Short-term rental units deployed to cover South routes since March 2026
A18: Age profile of collection trucks (units)
A19: Territory | B19: 0-4 years | C19: 5-8 years | D19: 9-12 years | E19: 13+ years | F19: Total | G19: Average age (years)
A20: North | B20: 22 | C20: 26 | D20: 8 | E20: 2 | F20: =SUM(B20:E20) -> 58 | G20: 5.6
A21: South | B21: 6 | C21: 17 | D21: 21 | E21: 10 | F21: =SUM(B21:E21) -> 54 | G21: 9.4
A22: East | B22: 14 | C22: 17 | D22: 8 | E22: 1 | F22: =SUM(B22:E22) -> 40 | G22: 6
A24: Planned replacement cycle: 9 years for front-load and rear-load, 10 years for roll-off. Average replacement cost per collection truck: $345,000.

Sheet Customers & Contracts
A1: HARROW RIDGE ENVIRONMENTAL SERVICES
A2: Largest Customer Relationships and Contract Renewals
A3: $ in thousands
A4: Accrual basis, US GAAP, unaudited management accounts. Finance leases recognized under ASC 842. Synthetic test data. Fictional company; not based on any real business.
A6: Customer | B6: Territory | C6: Service | D6: FY2026 revenue ($000) | E6: % of total revenue | F6: Contract end | G6: Escalator | H6: Renewal status
A7: National Account 01 (grocery chain, 38 sites) | B7: North / East | C7: Front-load, compactors | D7: 2860 | E7: =D7/'P&L Summary'!F13 -> 0.06130761 | F7: Dec 31, 2026 | G7: CPI, capped 3% | H7: RFP issued Aug-26; incumbent bid submitted at 8% below current pricing
A8: Regional Hospital System A | B8: North | C8: Front-load, medical-adjacent | D8: 1180 | E8: =D8/'P&L Summary'!F13 -> 0.025294748 | F8: Jun 30, 2028 | G8: Fixed 4% | H8: Long-term contract
A9: Distribution Park Owner B | B9: South | C9: Roll-off, compactors | D9: 940 | E9: =D9/'P&L Summary'!F13 -> 0.020150054 | F9: Mar 31, 2027 | G9: CPI, capped 3% | H9: Renewal discussions not started
A10: University Campus C | B10: East | C10: Front-load, recycling | D10: 870 | E10: =D10/'P&L Summary'!F13 -> 0.018649518 | F10: Aug 31, 2029 | G10: CPI | H10: Renewed Aug-26 at +3.5%
A11: Property Manager D (42 buildings) | B11: North | C11: Front-load | D11: 810 | E11: =D11/'P&L Summary'!F13 -> 0.017363344 | F11: Sep 30, 2027 | G11: Fixed 5%
A12: Food Processor E | B12: East | C12: Roll-off, organics | D12: 690 | E12: =D12/'P&L Summary'!F13 -> 0.014790997 | F12: Dec 31, 2027 | G12: CPI, capped 3%
A13: Municipal Facilities F | B13: South | C13: Roll-off | D13: 620 | E13: =D13/'P&L Summary'!F13 -> 0.013290461 | F13: Jun 30, 2027 | G13: CPI
A14: Hotel Group G | B14: North | C14: Front-load | D14: 540 | E14: =D14/'P&L Summary'!F13 -> 0.011575563 | F14: Apr 30, 2028 | G14: Fixed 4% | H14: Won Apr-26 (new)
A15: Industrial Park H | B15: East | C15: Roll-off | D15: 510 | E15: =D15/'P&L Summary'!F13 -> 0.010932476 | F15: Mar 31, 2028 | G15: CPI | H15: Won Feb-26 (new)
A16: Retail Center Owner I | B16: South | C16: Front-load | D16: 470 | E16: =D16/'P&L Summary'!F13 -> 0.010075027 | F16: Nov 30, 2026 | G16: CPI, capped 3% | H16: Customer requested proposal from competitor
A18: New contract wins, FY2026 (annualized revenue, $000)
A19: North | D19: 1240
A20: South | D20: 120
A21: East | D21: 610

Sheet Adjusted EBITDA
A1: HARROW RIDGE ENVIRONMENTAL SERVICES
A2: Adjusted EBITDA, Fiscal Year 2026
A3: $ in thousands
A4: Accrual basis, US GAAP, unaudited management accounts. Finance leases recognized under ASC 842. Synthetic test data. Fictional company; not based on any real business.
A6: Item | B6: FY2026 | C6: Basis
A7: EBITDA, as reported | B7: ='P&L Summary'!F34 -> 9712 | C7: P&L Summary
A8: Sponsor management fee | B8: ='P&L Summary'!F31 -> 600 | C8: Contractual; non-operating
A9: Recycling commodity price normalization | B9: 735 | C9: Restates FY2026 recycling tons (28,800) at the three-year average price of $118/ton
A10: South fleet transition costs (truck rental) | B10: ='P&L Summary'!F19 -> 410 | C10: Temporary rental while South fleet is refreshed
A11: Adjusted EBITDA | B11: =SUM(B7:B10) -> 11457
A12: Adjusted EBITDA margin | B12: =IF('P&L Summary'!F13=0,0,B11/'P&L Summary'!F13) -> 0.24559486
