Workbook

Sheet CFO Commentary
A1: Summit Home Services Group: September 2026 Management Commentary
A2: From: Chief Financial Officer | To: Sponsor deal team | Synthetic test data. Fictional company; not based on any real business.
A4: Summary
A5: September net revenue of $3.30 million finished ahead of budget, extending a strong summer. Replacement demand remained healthy and our average ticket continued to climb on both service calls and installations. EBITDA came in below plan, which we attribute primarily to weather-driven overtime during an unusually warm first half of the month. We view this as timing and do not expect it to recur into the shoulder season.
A7: Gross margin
A8: Gross margin was lower than budget because of the overtime noted above. Equipment and material costs were broadly in line with expectations, and we continue to pass through manufacturer price changes on a timely basis.
A10: Branches
A11: Northern had a record month on revenue and contribution. Central performed in line with plan. Lakeshore was softer than budget after two senior technician departures in August; we have backfilled one role and expect the branch to return to plan in Q4. Service quality across the branches remains consistent with historical levels.
A13: Comfort Club
A14: The Comfort Club membership base reached a record 13,661 active agreements at month-end, supported by strong new-agreement sales attached to summer installations. Recurring maintenance revenue remains a stable foundation for the business.
A16: Working capital
A17: Collections remained solid. Receivables increased modestly with higher seasonal volume, and the majority of the balance is current, including amounts due from our consumer financing partner that typically fund within a few days.
... A20: We expect October and November to benefit from heating-season tune-ups and a healthy installation backlog. We are reaffirming the full-year EBITDA budget and expect the September shortfall to be recovered in Q4.

Sheet Income Statement
A1: Summit Home Services Group
A2: Consolidated Income Statement
A3: Month and Year to Date Ended September 30, 2026 | ($ in thousands)
A4: Synthetic test data. Fictional company; not based on any real business.
C6: MONTH | J6: YEAR TO DATE
A7: Acct | B7: Description | C7: Sep-26 Budget | D7: Sep-26 Actual | E7: Fav / (Unfav) $ | F7: Fav / (Unfav) % | G7: Aug-26 Actual | H7: Sep-25 Actual | J7: YTD Budget | K7: YTD Actual | L7: Fav / (Unfav) $ | M7: Fav / (Unfav) % | N7: YTD Prior Year
B8: REVENUE
A9: 4010 | B9: HVAC Replacement & Installation | C9: 1309 | D9: ='Monthly Detail'!K8 -> 1352 | E9: =D9-C9 -> 43 | F9: =IF(C9=0,0,E9/ABS(C9)) -> 0.032849503 | G9: ='Monthly Detail'!J8 -> 1599 | H9: 1221 | J9: 11641 | K9: ='Monthly Detail'!L8 -> 12053 | L9: =K9-J9 -> 412 | M9: =IF(J9=0,0,L9/ABS(J9)) -> 0.035392148 | N9: 10856
A10: 4020 | B10: HVAC Repair & Service Calls | C10: 748 | D10: ='Monthly Detail'!K9 -> 777 | E10: =D10-C10 -> 29 | F10: =IF(C10=0,0,E10/ABS(C10)) -> 0.038770053 | G10: ='Monthly Detail'!J9 -> 933 | H10: 698 | J10: 6652 | K10: ='Monthly Detail'!L9 -> 6908 | L10: =K10-J10 -> 256 | M10: =IF(J10=0,0,L10/ABS(J10)) -> 0.038484666 | N10: 6204
A11: 4110 | B11: Plumbing Repair & Drain Service | C11: 546 | D11: ='Monthly Detail'!K10 -> 566 | E11: =D11-C11 -> 20 | F11: =IF(C11=0,0,E11/ABS(C11)) -> 0.036630037 | G11: ='Monthly Detail'!J10 -> 619 | H11: 509 | J11: 4883 | K11: ='Monthly Detail'!L10 -> 5077 | L11: =K11-J11 -> 194 | M11: =IF(J11=0,0,L11/ABS(J11)) -> 0.039729674 | N11: 4554
A12: 4120 | B12: Plumbing Installation (Water Heaters, Repipes) | C12: 321 | D12: ='Monthly Detail'!K11 -> 329 | E12: =D12-C12 -> 8 | F12: =IF(C12=0,0,E12/ABS(C12)) -> 0.024922118 | G12: ='Monthly Detail'!J11 -> 358 | H12: 299 | J12: 2874 | K12: ='Monthly Detail'!L11 -> 2978 | L12: =K12-J12 -> 104 | M12: =IF(J12=0,0,L12/ABS(J12)) -> 0.0361865 | N12: 2681
A13: 4210 | B13: Comfort Club Maintenance Agreements | C13: 335 | D13: ='Monthly Detail'!K12 -> 328 | E13: =D13-C13 -> -7 | F13: =IF(C13=0,0,E13/ABS(C13)) -> -0.020895522 | G13: ='Monthly Detail'!J12 -> 327 | H13: 292 | J13: 2870 | K13: ='Monthly Detail'!L12 -> 2858 | L13: =K13-J13 -> -12 | M13: =IF(J13=0,0,L13/ABS(J13)) -> -0.0041811847 | N13: 2600
A14: 4900 | B14: Discounts, Coupons & Warranty Credits | C14: -52 | D14: ='Monthly Detail'!K13 -> -54 | E14: =D14-C14 -> -2 | F14: =IF(C14=0,0,E14/ABS(C14)) -> -0.038461538 | G14: ='Monthly Detail'!J13 -> -61 | H14: -48 | J14: -462 | K14: ='Monthly Detail'!L13 -> -478 | L14: =K14-J14 -> -16 | M14: =IF(J14=0,0,L14/ABS(J14)) -> -0.034632035 | N14: -431
B15: Net Revenue | C15: =SUM(C9:C14) -> 3207 | D15: =SUM(D9:D14) -> 3298 | E15: =D15-C15 -> 91 | F15: =IF(C15=0,0,E15/ABS(C15)) -> 0.028375429 | G15: =SUM(G9:G14) -> 3775 | H15: =SUM(H9:H14) -> 2971 | J15: =SUM(J9:J14) -> 28458 | K15: =SUM(K9:K14) -> 29396 | L15: =K15-J15 -> 938 | M15: =IF(J15=0,0,L15/ABS(J15)) -> 0.032960855 | N15: =SUM(N9:N14) -> 26464
B17: COST OF SERVICES
A18: 5010 | B18: Technician Wages - Straight Time | C18: 652 | D18: ='Monthly Detail'!K17 -> 670 | E18: =C18-D18 -> -18 | F18: =IF(C18=0,0,E18/ABS(C18)) -> -0.027607362 | G18: ='Monthly Detail'!J17 -> 767 | H18: 604 | J18: 5785 | K18: ='Monthly Detail'!L17 -> 5973 | L18: =J18-K18 -> -188 | M18: =IF(J18=0,0,L18/ABS(J18)) -> -0.032497839 | N18: 5379
A19: 5020 | B19: Technician Wages - Overtime | C19: 65 | D19: ='Monthly Detail'!K18 -> 164 | E19: =C19-D19 -> -99 | F19: =IF(C19=0,0,E19/ABS(C19)) -> -1.5230769 | G19: ='Monthly Detail'!J18 -> 176 | H19: 51 | J19: 578 | K19: ='Monthly Detail'!L18 -> 962 | L19: =J19-K19 -> -384 | M19: =IF(J19=0,0,L19/ABS(J19)) -> -0.66435986 | N19: 457
A20: 5030 | B20: Field Payroll Taxes & Benefits | C20: 151 | D20: ='Monthly Detail'!K19 -> 175 | E20: =C20-D20 -> -24 | F20: =IF(C20=0,0,E20/ABS(C20)) -> -0.1589404 | G20: ='Monthly Detail'!J19 -> 198 | H20: 138 | J20: 1338 | K20: ='Monthly Detail'!L19 -> 1456 | L20: =J20-K20 -> -118 | M20: =IF(J20=0,0,L20/ABS(J20)) -> -0.08819133 | N20: 1226
A21: 5110 | B21: HVAC Equipment (Condensers, Furnaces, Air Handlers) | C21: 412 | D21: ='Monthly Detail'!K20 -> 495 | E21: =C21-D21 -> -83 | F21: =IF(C21=0,0,E21/ABS(C21)) -> -0.20145631 | G21: ='Monthly Detail'!J20 -> 576 | H21: 385 | J21: 3665 | K21: ='Monthly Detail'!L20 -> 4144 | L21: =J21-K21 -> -479 | M21: =IF(J21=0,0,L21/ABS(J21)) -> -0.13069577 | N21: 3420
A22: 5120 | B22: Parts, Fittings & Job Materials | C22: 197 | D22: ='Monthly Detail'!K21 -> 203 | E22: =C22-D22 -> -6 | F22: =IF(C22=0,0,E22/ABS(C22)) -> -0.030456853 | G22: ='Monthly Detail'!J21 -> 229 | H22: 183 | J22: 1757 | K22: ='Monthly Detail'!L21 -> 1822 | L22: =J22-K22 -> -65 | M22: =IF(J22=0,0,L22/ABS(J22)) -> -0.036994878 | N22: 1638
A23: 5210 | B23: Subcontracted Electrical & Permits | C23: 39 | D23: ='Monthly Detail'!K22 -> 41 | E23: =C23-D23 -> -2 | F23: =IF(C23=0,0,E23/ABS(C23)) -> -0.051282051 | G23: ='Monthly Detail'!J22 -> 48 | H23: 37 | J23: 349 | K23: ='Monthly Detail'!L22 -> 362 | L23: =J23-K23 -> -13 | M23: =IF(J23=0,0,L23/ABS(J23)) -> -0.037249284 | N23: 326
A24: 5310 | B24: Fleet - Fuel, Lease & Maintenance | C24: 114 | D24: ='Monthly Detail'!K23 -> 117 | E24: =C24-D24 -> -3 | F24: =IF(C24=0,0,E24/ABS(C24)) -> -0.026315789 | G24: ='Monthly Detail'!J23 -> 134 | H24: 106 | J24: 1013 | K24: ='Monthly Detail'!L23 -> 1044 | L24: =J24-K24 -> -31 | M24: =IF(J24=0,0,L24/ABS(J24)) -> -0.030602172 | N24: 941
B25: Total Cost of Services | C25: =SUM(C18:C24) -> 1630 | D25: =SUM(D18:D24) -> 1865 | E25: =C25-D25 -> -235 | F25: =IF(C25=0,0,E25/ABS(C25)) -> -0.14417178 | G25: =SUM(G18:G24) -> 2128 | H25: =SUM(H18:H24) -> 1504 | J25: =SUM(J18:J24) -> 14485 | K25: =SUM(K18:K24) -> 15763 | L25: =J25-K25 -> -1278 | M25: =IF(J25=0,0,L25/ABS(J25)) -> -0.088229203 | N25: =SUM(N18:N24) -> 13387
B26: Gross Profit | C26: =C15-C25 -> 1577 | D26: =D15-D25 -> 1433 | E26: =D26-C26 -> -144 | F26: =IF(C26=0,0,E26/ABS(C26)) -> -0.091312619 | G26: =G15-G25 -> 1647 | H26: =H15-H25 -> 1467 | J26: =J15-J25 -> 13973 | K26: =K15-K25 -> 13633 | L26: =K26-J26 -> -340 | M26: =IF(J26=0,0,L26/ABS(J26)) -> -0.024332642 | N26: =N15-N25 -> 13077
B27: Gross Margin % | C27: =IF(C15=0,0,C26/C15) -> 0.49173683 | D27: =IF(D15=0,0,D26/D15) -> 0.43450576 | G27: =IF(G15=0,0,G26/G15) -> 0.43629139 | H27: =IF(H15=0,0,H26/H15) -> 0.49377314 | J27: =IF(J15=0,0,J26/J15) -> 0.49100429 | K27: =IF(K15=0,0,K26/K15) -> 0.46377058 | N27: =IF(N15=0,0,N26/N15) -> 0.49414299
B29: OPERATING EXPENSES
A30: 6010 | B30: CSR, Dispatch & Office Salaries | C30: 212 | D30: ='Monthly Detail'!K29 -> 212 | E30: =C30-D30 -> 0 | F30: =IF(C30=0,0,E30/ABS(C30)) -> 0 | G30: ='Monthly Detail'!J29 -> 212 | H30: 212 | J30: 1908 | K30: ='Monthly Detail'!L29 -> 1908 | L30: =J30-K30 -> 0 | M30: =IF(J30=0,0,L30/ABS(J30)) -> 0 | N30: 1908
A31: 6020 | B31: Branch & Corporate Management Salaries | C31: 160 | D31: ='Monthly Detail'!K30 -> 160 | E31: =C31-D31 -> 0 | F31: =IF(C31=0,0,E31/ABS(C31)) -> 0 | G31: ='Monthly Detail'!J30 -> 160 | H31: 160 | J31: 1440 | K31: ='Monthly Detail'!L30 -> 1440 | L31: =J31-K31 -> 0 | M31: =IF(J31=0,0,L31/ABS(J31)) -> 0 | N31: 1440
A32: 6030 | B32: Office Payroll Taxes & Benefits | C32: 74 | D32: ='Monthly Detail'!K31 -> 74 | E32: =C32-D32 -> 0 | F32: =IF(C32=0,0,E32/ABS(C32)) -> 0 | G32: ='Monthly Detail'!J31 -> 74 | H32: 74 | J32: 666 | K32: ='Monthly Detail'!L31 -> 666 | L32: =J32-K32 -> 0 | M32: =IF(J32=0,0,L32/ABS(J32)) -> 0 | N32: 666
A33: 6110 | B33: Marketing, Lead Gen & Digital Ads | C33: 189 | D33: ='Monthly Detail'!K32 -> 194 | E33: =C33-D33 -> -5 | F33: =IF(C33=0,0,E33/ABS(C33)) -> -0.026455026 | G33: ='Monthly Detail'!J32 -> 223 | H33: 175 | J33: 1678 | K33: ='Monthly Detail'!L32 -> 1733 | L33: =J33-K33 -> -55 | M33: =IF(J33=0,0,L33/ABS(J33)) -> -0.032777116 | N33: 1559
A34: 6120 | B34: Field Service Software & Call Center | C34: 48 | D34: ='Monthly Detail'!K33 -> 48 | E34: =C34-D34 -> 0 | F34: =IF(C34=0,0,E34/ABS(C34)) -> 0 | G34: ='Monthly Detail'!J33 -> 48 | H34: 48 | J34: 432 | K34: ='Monthly Detail'!L33 -> 432 | L34: =J34-K34 -> 0 | M34: =IF(J34=0,0,L34/ABS(J34)) -> 0 | N34: 432
A35: 6210 | B35: Branch Facility Rent | C35: 62 | D35: ='Monthly Detail'!K34 -> 62 | E35: =C35-D35 -> 0 | F35: =IF(C35=0,0,E35/ABS(C35)) -> 0 | G35: ='Monthly Detail'!J34 -> 62 | H35: 62 | J35: 558 | K35: ='Monthly Detail'!L34 -> 558 | L35: =J35-K35 -> 0 | M35: =IF(J35=0,0,L35/ABS(J35)) -> 0 | N35: 558
A36: 6220 | B36: Utilities & Telecom | C36: 14 | D36: ='Monthly Detail'!K35 -> 14 | E36: =C36-D36 -> 0 | F36: =IF(C36=0,0,E36/ABS(C36)) -> 0 | G36: ='Monthly Detail'!J35 -> 14 | H36: 14 | J36: 126 | K36: ='Monthly Detail'!L35 -> 126 | L36: =J36-K36 -> 0 | M36: =IF(J36=0,0,L36/ABS(J36)) -> 0 | N36: 126
A37: 6310 | B37: General Liability, Auto & Umbrella Insurance | C37: 41 | D37: ='Monthly Detail'!K36 -> 41 | E37: =C37-D37 -> 0 | F37: =IF(C37=0,0,E37/ABS(C37)) -> 0 | G37: ='Monthly Detail'!J36 -> 41 | H37: 41 | J37: 369 | K37: ='Monthly Detail'!L36 -> 369 | L37: =J37-K37 -> 0 | M37: =IF(J37=0,0,L37/ABS(J37)) -> 0 | N37: 369
A38: 6410 | B38: Accounting, Legal & Professional Fees | C38: 22 | D38: ='Monthly Detail'!K37 -> 22 | E38: =C38-D38 -> 0 | F38: =IF(C38=0,0,E38/ABS(C38)) -> 0 | G38: ='Monthly Detail'!J37 -> 22 | H38: 22 | J38: 198 | K38: ='Monthly Detail'!L37 -> 198 | L38: =J38-K38 -> 0 | M38: =IF(J38=0,0,L38/ABS(J38)) -> 0 | N38: 198
A39: 6420 | B39: Sponsor Management Fee | C39: 50 | D39: ='Monthly Detail'!K38 -> 50 | E39: =C39-D39 -> 0 | F39: =IF(C39=0,0,E39/ABS(C39)) -> 0 | G39: ='Monthly Detail'!J38 -> 50 | H39: 50 | J39: 450 | K39: ='Monthly Detail'!L38 -> 450 | L39: =J39-K39 -> 0 | M39: =IF(J39=0,0,L39/ABS(J39)) -> 0 | N39: 450
A40: 6510 | B40: Technician Training & Recruiting | C40: 16 | D40: ='Monthly Detail'!K39 -> 24 | E40: =C40-D40 -> -8 | F40: =IF(C40=0,0,E40/ABS(C40)) -> -0.5 | G40: ='Monthly Detail'!J39 -> 24 | H40: 16 | J40: 144 | K40: ='Monthly Detail'!L39 -> 176 | L40: =J40-K40 -> -32 | M40: =IF(J40=0,0,L40/ABS(J40)) -> -0.22222222 | N40: 144
A41: 6900 | B41: Other G&A | C41: 30 | D41: ='Monthly Detail'!K40 -> 30 | E41: =C41-D41 -> 0 | F41: =IF(C41=0,0,E41/ABS(C41)) -> 0 | G41: ='Monthly Detail'!J40 -> 30 | H41: 30 | J41: 270 | K41: ='Monthly Detail'!L40 -> 270 | L41: =J41-K41 -> 0 | M41: =IF(J41=0,0,L41/ABS(J41)) -> 0 | N41: 270
B42: Total Operating Expenses | C42: =SUM(C30:C41) -> 918 | D42: =SUM(D30:D41) -> 931 | E42: =C42-D42 -> -13 | F42: =IF(C42=0,0,E42/ABS(C42)) -> -0.01416122 | G42: =SUM(G30:G41) -> 960 | H42: =SUM(H30:H41) -> 904 | J42: =SUM(J30:J41) -> 8239 | K42: =SUM(K30:K41) -> 8326 | L42: =J42-K42 -> -87 | M42: =IF(J42=0,0,L42/ABS(J42)) -> -0.010559534 | N42: =SUM(N30:N41) -> 8120
B44: EBITDA | C44: =C26-C42 -> 659 | D44: =D26-D42 -> 502 | E44: =D44-C44 -> -157 | F44: =IF(C44=0,0,E44/ABS(C44)) -> -0.23823976 | G44: =G26-G42 -> 687 | H44: =H26-H42 -> 563 | J44: =J26-J42 -> 5734 | K44: =K26-K42 -> 5307 | L44: =K44-J44 -> -427 | M44: =IF(J44=0,0,L44/ABS(J44)) -> -0.074468085 | N44: =N26-N42 -> 4957
...

Sheet Branch Results
A1: Summit Home Services Group
A2: Branch Results, September 2026
A3: ($ in thousands unless noted)
A4: Synthetic test data. Fictional company; not based on any real business.
C6: Northern (Ridgefield) | F6: Central (Maple Grove) | I6: Lakeshore (Port Haven) | L6: Total Branches
C7: Actual | D7: Budget | F7: Actual | G7: Budget | I7: Actual | J7: Budget | L7: Actual | M7: Budget
B8: Net Revenue | C8: 1359 | D8: 1251 | F8: 1154 | G8: 1090 | I8: 785 | J8: 866 | L8: =C8+F8+I8 -> 3298 | M8: =D8+G8+J8 -> 3207
B9: Cost of Services | C9: 731 | D9: 636 | F9: 593 | G9: 554 | I9: 494 | J9: 440 | L9: =C9+F9+I9 -> 1818 | M9: =D9+G9+J9 -> 1630
B10: Gross Profit | C10: =C8-C9 -> 628 | D10: =D8-D9 -> 615 | F10: =F8-F9 -> 561 | G10: =G8-G9 -> 536 | I10: =I8-I9 -> 291 | J10: =J8-J9 -> 426 | L10: =C10+F10+I10 -> 1480 | M10: =D10+G10+J10 -> 1577
B11: Gross Margin % | C11: =IF(C8=0,0,C10/C8) -> 0.46210449 | D11: =IF(D8=0,0,D10/D8) -> 0.49160671 | F11: =IF(F8=0,0,F10/F8) -> 0.48613518 | G11: =IF(G8=0,0,G10/G8) -> 0.49174312 | I11: =IF(I8=0,0,I10/I8) -> 0.37070064 | J11: =IF(J8=0,0,J10/J8) -> 0.49191686 | L11: =IF(L8=0,0,L10/L8) -> 0.44875682 | M11: =IF(M8=0,0,M10/M8) -> 0.49173683
B12: Branch Operating Expenses | C12: 179 | D12: 177 | F12: 165 | G12: 162 | I12: 152 | J12: 138 | L12: =C12+F12+I12 -> 496 | M12: =D12+G12+J12 -> 477
B13: Branch Contribution | C13: =C10-C12 -> 449 | D13: =D10-D12 -> 438 | F13: =F10-F12 -> 396 | G13: =G10-G12 -> 374 | I13: =I10-I12 -> 139 | J13: =J10-J12 -> 288 | L13: =C13+F13+I13 -> 984 | M13: =D13+G13+J13 -> 1100
B14: Contribution Margin % | C14: =IF(C8=0,0,C13/C8) -> 0.33038999 | D14: =IF(D8=0,0,D13/D8) -> 0.3501199 | F14: =IF(F8=0,0,F13/F8) -> 0.34315425 | G14: =IF(G8=0,0,G13/G8) -> 0.34311927 | I14: =IF(I8=0,0,I13/I8) -> 0.17707006 | J14: =IF(J8=0,0,J13/J8) -> 0.33256351 | L14: =IF(L8=0,0,L13/L8) -> 0.29836264 | M14: =IF(M8=0,0,M13/M8) -> 0.34299969
B16: Reconciliation to Company EBITDA
B17: Total Branch Contribution | L17: =L13 -> 984 | M17: =M13 -> 1100
B18: Less: Corporate & Unallocated Overhead | L18: 435 | M18: 441
B19: Company EBITDA | L19: =L17-L18 -> 549 | M19: =M17-M18 -> 659
B21: Branch Operating Metrics (Actual)
B22: Technicians (headcount) | C22: 45 | F22: 39 | I22: 27 | L22: =C22+F22+I22 -> 111
B23: Service calls completed | C23: 1153 | F23: 1009 | I23: 720 | L23: =C23+F23+I23 -> 2882
B24: Callbacks (repeat visits within 30 days) | C24: 36 | F24: 36 | I24: 56 | L24: =C24+F24+I24 -> 128
B25: Callback rate | C25: =IF(C23=0,0,C24/C23) -> 0.031222897 | F25: =IF(F23=0,0,F24/F23) -> 0.03567889 | I25: =IF(I23=0,0,I24/I23) -> 0.077777778 | L25: =IF(L23=0,0,L24/L23) -> 0.044413602
B26: Technician utilization (billable / paid hours) | C26: 0.768 | F26: 0.741 | I26: 0.682
B27: Revenue per technician ($000) | C27: =IF(C22=0,0,C8/C22) -> 30.2 | F27: =IF(F22=0,0,F8/F22) -> 29.589744 | I27: =IF(I22=0,0,I8/I22) -> 29.074074

Sheet Operating Metrics
A1: Summit Home Services Group
A2: Operating Metrics, January to September 2026
A3: Synthetic test data. Fictional company; not based on any real business.
A5: Metric | B5: Unit | C5: Jan-26 | D5: Feb-26 | E5: Mar-26 | F5: Apr-26 | G5: May-26 | H5: Jun-26 | I5: Jul-26 | J5: Aug-26 | K5: Sep-26
A6: Service
A7: Service calls completed (HVAC + plumbing repair) | B7: # | C7: 2679 | D7: 2584 | E7: 2768 | F7: 2863 | G7: 3107 | H7: 3365 | I7: 3521 | J7: 3381 | K7: 2882
A8: Repair & service revenue | B8: $000 | C8: ='Monthly Detail'!C9+'Monthly Detail'!C10 -> 1120 | D8: ='Monthly Detail'!D9+'Monthly Detail'!D10 -> 1088 | E8: ='Monthly Detail'!E9+'Monthly Detail'!E10 -> 1179 | F8: ='Monthly Detail'!F9+'Monthly Detail'!F10 -> 1237 | G8: ='Monthly Detail'!G9+'Monthly Detail'!G10 -> 1367 | H8: ='Monthly Detail'!H9+'Monthly Detail'!H10 -> 1504 | I8: ='Monthly Detail'!I9+'Monthly Detail'!I10 -> 1595 | J8: ='Monthly Detail'!J9+'Monthly Detail'!J10 -> 1552 | K8: ='Monthly Detail'!K9+'Monthly Detail'!K10 -> 1343
A9: Average revenue per service call | B9: $ | C9: =IF(C7=0,0,C8*1000/C7) -> 418.06644 | D9: =IF(D7=0,0,D8*1000/D7) -> 421.05263 | E9: =IF(E7=0,0,E8*1000/E7) -> 425.93931 | F9: =IF(F7=0,0,F8*1000/F7) -> 432.06427 | G9: =IF(G7=0,0,G8*1000/G7) -> 439.97425 | H9: =IF(H7=0,0,H8*1000/H7) -> 446.95394 | I9: =IF(I7=0,0,I8*1000/I7) -> 452.99631 | J9: =IF(J7=0,0,J8*1000/J7) -> 459.03579 | K9: =IF(K7=0,0,K8*1000/K7) -> 465.99584
A10: Callbacks (repeat visits within 30 days) | B10: # | C10: 86 | D10: 80 | E10: 91 | F10: 97 | G10: 109 | H10: 125 | I10: 137 | J10: 142 | K10: 128
A11: Callback rate | B11: % | C11: =IF(C7=0,0,C10/C7) -> 0.03210153 | D11: =IF(D7=0,0,D10/D7) -> 0.030959752 | E11: =IF(E7=0,0,E10/E7) -> 0.032875723 | F11: =IF(F7=0,0,F10/F7) -> 0.033880545 | G11: =IF(G7=0,0,G10/G7) -> 0.035082073 | H11: =IF(H7=0,0,H10/H7) -> 0.037147103 | I11: =IF(I7=0,0,I10/I7) -> 0.038909401 | J11: =IF(J7=0,0,J10/J7) -> 0.041999408 | K11: =IF(K7=0,0,K10/K7) -> 0.044413602
A12: Installation
A13: HVAC systems installed | B13: # | C13: 90 | D13: 87 | E13: 97 | F13: 103 | G13: 115 | H13: 127 | I13: 136 | J13: 130 | K13: 109
A14: Average HVAC install ticket | B14: $ | C14: =IF(C13=0,0,'Monthly Detail'!C8*1000/C13) -> 11844.444 | D14: =IF(D13=0,0,'Monthly Detail'!D8*1000/D13) -> 11954.023 | E14: =IF(E13=0,0,'Monthly Detail'!E8*1000/E13) -> 11907.216 | F14: =IF(F13=0,0,'Monthly Detail'!F8*1000/F13) -> 12077.67 | G14: =IF(G13=0,0,'Monthly Detail'!G8*1000/G13) -> 12069.565 | H14: =IF(H13=0,0,'Monthly Detail'!H8*1000/H13) -> 12196.85 | I14: =IF(I13=0,0,'Monthly Detail'!I8*1000/I13) -> 12205.882 | J14: =IF(J13=0,0,'Monthly Detail'!J8*1000/J13) -> 12300 | K14: =IF(K13=0,0,'Monthly Detail'!K8*1000/K13) -> 12403.67
A15: Equipment cost as % of HVAC install revenue | B15: % | C15: =IF('Monthly Detail'!C8=0,0,'Monthly Detail'!C20/'Monthly Detail'!C8) -> 0.31988743 | D15: =IF('Monthly Detail'!D8=0,0,'Monthly Detail'!D20/'Monthly Detail'!D8) -> 0.32019231 | E15: =IF('Monthly Detail'!E8=0,0,'Monthly Detail'!E20/'Monthly Detail'!E8) -> 0.32207792 | F15: =IF('Monthly Detail'!F8=0,0,'Monthly Detail'!F20/'Monthly Detail'!F8) -> 0.335209 | G15: =IF('Monthly Detail'!G8=0,0,'Monthly Detail'!G20/'Monthly Detail'!G8) -> 0.34510086 | H15: =IF('Monthly Detail'!H8=0,0,'Monthly Detail'!H20/'Monthly Detail'!H8) -> 0.34990316 | I15: =IF('Monthly Detail'!I8=0,0,'Monthly Detail'!I20/'Monthly Detail'!I8) -> 0.35481928 | J15: =IF('Monthly Detail'!J8=0,0,'Monthly Detail'!J20/'Monthly Detail'!J8) -> 0.36022514 | K15: =IF('Monthly Detail'!K8=0,0,'Monthly Detail'!K20/'Monthly Detail'!K8) -> 0.36612426
A16: Installation backlog (sold, not yet installed) | B16: $000 | C16: 610 | D16: 645 | E16: 720 | F16: 880 | G16: 1050 | H16: 1180 | I16: 1235 | J16: 1210 | K16: 1265
A17: Workforce
A18: Technicians (headcount, month-end) | B18: # | C18: 96 | D18: 96 | E18: 98 | F18: 101 | G18: 105 | H18: 109 | I18: 112 | J18: 112 | K18: 111
A19: Technician utilization (billable / paid hours) | B19: % | C19: 0.712 | D19: 0.708 | E19: 0.716 | F19: 0.722 | G19: 0.731 | H19: 0.744 | I19: 0.748 | J19: 0.741 | K19: 0.738
A20: Overtime as % of technician wages | B20: % | C20: =IF(('Monthly Detail'!C17+'Monthly Detail'!C18)=0,0,'Monthly Detail'!C18/('Monthly Detail'!C17+'Monthly Detail'!C18)) -> 0.081967213 | D20: =IF(('Monthly Detail'!D17+'Monthly Detail'!D18)=0,0,'Monthly Detail'!D18/('Monthly Detail'!D17+'Monthly Detail'!D18)) -> 0.082214765 | E20: =IF(('Monthly Detail'!E17+'Monthly Detail'!E18)=0,0,'Monthly Detail'!E18/('Monthly Detail'!E17+'Monthly Detail'!E18)) -> 0.090769231 | F20: =IF(('Monthly Detail'!F17+'Monthly Detail'!F18)=0,0,'Monthly Detail'!F18/('Monthly Detail'!F17+'Monthly Detail'!F18)) -> 0.0995671 | G20: =IF(('Monthly Detail'!G17+'Monthly Detail'!G18)=0,0,'Monthly Detail'!G18/('Monthly Detail'!G17+'Monthly Detail'!G18)) -> 0.12242268 | H20: =IF(('Monthly Detail'!H17+'Monthly Detail'!H18)=0,0,'Monthly Detail'!H18/('Monthly Detail'!H17+'Monthly Detail'!H18)) -> 0.15244596 | I20: =IF(('Monthly Detail'!I17+'Monthly Detail'!I18)=0,0,'Monthly Detail'!I18/('Monthly Detail'!I17+'Monthly Detail'!I18)) -> 0.17400419 | J20: =IF(('Monthly Detail'!J17+'Monthly Detail'!J18)=0,0,'Monthly Detail'!J18/('Monthly Detail'!J17+'Monthly Detail'!J18)) -> 0.18663839 | K20: =IF(('Monthly Detail'!K17+'Monthly Detail'!K18)=0,0,'Monthly Detail'!K18/('Monthly Detail'!K17+'Monthly Detail'!K18)) -> 0.19664269
A21: Comfort Club (maintenance agreements)
A22: Agreements up for renewal | B22: # | C22: 1055 | D22: 1074 | E22: 1076 | F22: 1099 | G22: 1074 | H22: 1090 | I22: 1121 | J22: 1133 | K22: 1152
A23: Agreements renewed | B23: # | C23: 886 | D23: 891 | E23: 904 | F23: 901 | G23: 848 | H23: 839 | I23: 841 | J23: 827 | K23: 818
A24: Renewal rate | B24: % | C24: =IF(C22=0,0,C23/C22) -> 0.83981043 | D24: =IF(D22=0,0,D23/D22) -> 0.82960894 | E24: =IF(E22=0,0,E23/E22) -> 0.8401487 | F24: =IF(F22=0,0,F23/F22) -> 0.81983621 | G24: =IF(G22=0,0,G23/G22) -> 0.78957169 | H24: =IF(H22=0,0,H23/H22) -> 0.76972477 | I24: =IF(I22=0,0,I23/I22) -> 0.75022302 | J24: =IF(J22=0,0,J23/J22) -> 0.72992056 | K24: =IF(K22=0,0,K23/K22) -> 0.71006944
A25: New agreements sold | B25: # | C25: 210 | D25: 200 | E25: 260 | F25: 300 | G25: 360 | H25: 420 | I25: 440 | J25: 410 | K25: 330
A26: Active agreements, month-end | B26: # | C26: 12891 | D26: 12908 | E26: 12996 | F26: 13098 | G26: 13232 | H26: 13401 | I26: 13561 | J26: 13665 | K26: 13661

Sheet AR Aging & Recon
A1: Summit Home Services Group
A2: Accounts Receivable Aging as of September 30, 2026
A3: ($ in thousands)
A4: Synthetic test data. Fictional company; not based on any real business.
A6: Customer / Group | B6: Type | C6: Current | D6: 31-60 | E6: 61-90 | F6: Over 90 | G6: Total | H6: % of Total
A7: Consumer Financing Partner (funded installs) | B7: Financing | C7: 612 | D7: 18 | E7: 0 | F7: 0 | G7: =SUM(C7:F7) -> 630 | H7: =IF($G$15=0,0,G7/$G$15) -> 0.25362319
A8: Home Warranty Company A | B8: Warranty | C8: 176 | D8: 88 | E8: 31 | F8: 12 | G8: =SUM(C8:F8) -> 307 | H8: =IF($G$15=0,0,G8/$G$15) -> 0.12359098
A9: Home Warranty Company B | B9: Warranty | C9: 104 | D9: 42 | E9: 15 | F9: 6 | G9: =SUM(C9:F9) -> 167 | H9: =IF($G$15=0,0,G9/$G$15) -> 0.067230274
A10: Builder Customer 01 | B10: New construction | C10: 58 | D10: 46 | E10: 71 | F10: 292 | G10: =SUM(C10:F10) -> 467 | H10: =IF($G$15=0,0,G10/$G$15) -> 0.18800322
A11: Builder Customer 02 | B11: New construction | C11: 121 | D11: 37 | E11: 0 | F11: 0 | G11: =SUM(C11:F11) -> 158 | H11: =IF($G$15=0,0,G11/$G$15) -> 0.063607085
A12: Property Management Accounts (14) | B12: Commercial | C12: 196 | D12: 61 | E12: 18 | F12: 9 | G12: =SUM(C12:F12) -> 284 | H12: =IF($G$15=0,0,G12/$G$15) -> 0.11433172
A13: Light Commercial Accounts (22) | B13: Commercial | C13: 88 | D13: 24 | E13: 9 | F13: 4 | G13: =SUM(C13:F13) -> 125 | H13: =IF($G$15=0,0,G13/$G$15) -> 0.050322061
A14: Residential Open Invoices | B14: Residential | C14: 214 | D14: 63 | E14: 28 | F14: 41 | G14: =SUM(C14:F14) -> 346 | H14: =IF($G$15=0,0,G14/$G$15) -> 0.13929147
A15: Total Accounts Receivable | C15: =SUM(C7:C14) -> 1569 | D15: =SUM(D7:D14) -> 379 | E15: =SUM(E7:E14) -> 172 | F15: =SUM(F7:F14) -> 364 | G15: =SUM(G7:G14) -> 2484 | H15: =IF($G$15=0,0,G15/$G$15) -> 1
A16: % of total | C16: =IF($G$15=0,0,C15/$G$15) -> 0.63164251 | D16: =IF($G$15=0,0,D15/$G$15) -> 0.15257649 | E16: =IF($G$15=0,0,E15/$G$15) -> 0.069243156 | F16: =IF($G$15=0,0,F15/$G$15) -> 0.14653784
A18: Reconciliation to General Ledger
A19: AR per aging (above) | G19: =G15 -> 2484
A20: AR per GL, account 1200 Trade Receivables | G20: 2484
A21: Difference | G21: =G19-G20 -> 0
A22: Allowance for doubtful accounts, GL account 1290 | G22: -35
A23: Net accounts receivable | G23: =G20+G22 -> 2449
A25: Trend (month-end)
C26: Jun-26 | D26: Jul-26 | E26: Aug-26 | F26: Sep-26
A27: Total AR | C27: 2010 | D27: 2085 | E27: 2240 | F27: =G15 -> 2484
A28: Over 90 days | C28: 118 | D28: 142 | E28: 219 | F28: =F15 -> 364
A29: Monthly net revenue | C29: ='Monthly Detail'!H14 -> 3665 | D29: ='Monthly Detail'!I14 -> 3880 | E29: ='Monthly Detail'!J14 -> 3775 | F29: ='Monthly Detail'!K14 -> 3298
A30: DSO (AR / monthly revenue x 30) | C30: =IF(C29=0,0,C27/C29*30) -> 16.452933 | D30: =IF(D29=0,0,D27/D29*30) -> 16.121134 | E30: =IF(E29=0,0,E27/E29*30) -> 17.801325 | F30: =IF(F29=0,0,F27/F29*30) -> 22.595512

Sheet Monthly Detail
A1: Summit Home Services Group
A2: Monthly Income Statement Detail, January to September 2026
A3: ($ in thousands)
A4: Synthetic test data. Fictional company; not based on any real business.
A6: Acct | B6: Description | C6: Jan-26 | D6: Feb-26 | E6: Mar-26 | F6: Apr-26 | G6: May-26 | H6: Jun-26 | I6: Jul-26 | J6: Aug-26 | K6: Sep-26 | L6: YTD Total
B7: Revenue
A8: 4010 | B8: HVAC Replacement & Installation | C8: 1066 | D8: 1040 | E8: 1155 | F8: 1244 | G8: 1388 | H8: 1549 | I8: 1660 | J8: 1599 | K8: 1352 | L8: =SUM(C8:K8) -> 12053
A9: 4020 | B9: HVAC Repair & Service Calls | C9: 612 | D9: 588 | E9: 653 | F9: 701 | G9: 790 | H9: 893 | I9: 961 | J9: 933 | K9: 777 | L9: =SUM(C9:K9) -> 6908
A10: 4110 | B10: Plumbing Repair & Drain Service | C10: 508 | D10: 500 | E10: 526 | F10: 536 | G10: 577 | H10: 611 | I10: 634 | J10: 619 | K10: 566 | L10: =SUM(C10:K10) -> 5077
A11: 4120 | B11: Plumbing Installation (Water Heaters, Repipes) | C11: 306 | D11: 297 | E11: 313 | F11: 325 | G11: 334 | H11: 352 | I11: 364 | J11: 358 | K11: 329 | L11: =SUM(C11:K11) -> 2978
A12: 4210 | B12: Comfort Club Maintenance Agreements | C12: 309 | D12: 310 | E12: 311 | F12: 313 | G12: 316 | H12: 320 | I12: 324 | J12: 327 | K12: 328 | L12: =SUM(C12:K12) -> 2858
A13: 4900 | B13: Discounts, Coupons & Warranty Credits | C13: -45 | D13: -44 | E13: -47 | F13: -50 | G13: -54 | H13: -60 | I13: -63 | J13: -61 | K13: -54 | L13: =SUM(C13:K13) -> -478
B14: Net Revenue | C14: =SUM(C8:C13) -> 2756 | D14: =SUM(D8:D13) -> 2691 | E14: =SUM(E8:E13) -> 2911 | F14: =SUM(F8:F13) -> 3069 | G14: =SUM(G8:G13) -> 3351 | H14: =SUM(H8:H13) -> 3665 | I14: =SUM(I8:I13) -> 3880 | J14: =SUM(J8:J13) -> 3775 | ... L14: =SUM(L8:L13) -> 29396
B16: Cost of Services
A17: 5010 | B17: Technician Wages - Straight Time | C17: 560 | D17: 547 | E17: 591 | F17: 624 | G17: 681 | H17: 745 | I17: 788 | J17: 767 | K17: 670 | L17: =SUM(C17:K17) -> 5973
A18: 5020 | B18: Technician Wages - Overtime | C18: 50 | D18: 49 | E18: 59 | F18: 69 | G18: 95 | H18: 134 | I18: 166 | J18: 176 | K18: 164 | L18: =SUM(C18:K18) -> 962
A19: 5030 | B19: Field Payroll Taxes & Benefits | C19: 128 | D19: 125 | E19: 137 | F19: 145 | G19: 163 | H19: 185 | I19: 200 | J19: 198 | K19: 175 | L19: =SUM(C19:K19) -> 1456
A20: 5110 | B20: HVAC Equipment (Condensers, Furnaces, Air Handlers) | C20: 341 | D20: 333 | E20: 372 | F20: 417 | G20: 479 | H20: 542 | I20: 589 | J20: 576 | K20: 495 | L20: =SUM(C20:K20) -> 4144
A21: 5120 | B21: Parts, Fittings & Job Materials | C21: 177 | D21: 172 | E21: 184 | F21: 193 | G21: 207 | H21: 223 | I21: 234 | J21: 229 | K21: 203 | L21: =SUM(C21:K21) -> 1822
A22: 5210 | B22: Subcontracted Electrical & Permits | C22: 32 | D22: 31 | E22: 35 | F22: 37 | G22: 42 | H22: 46 | I22: 50 | J22: 48 | K22: 41 | L22: =SUM(C22:K22) -> 362
A23: 5310 | B23: Fleet - Fuel, Lease & Maintenance | C23: 98 | D23: 96 | E23: 103 | F23: 109 | G23: 119 | H23: 130 | I23: 138 | J23: 134 | K23: 117 | L23: =SUM(C23:K23) -> 1044
B24: Total Cost of Services | C24: =SUM(C17:C23) -> 1386 | D24: =SUM(D17:D23) -> 1353 | E24: =SUM(E17:E23) -> 1481 | F24: =SUM(F17:F23) -> 1594 | G24: =SUM(G17:G23) -> 1786 | H24: =SUM(H17:H23) -> 2005 | I24: =SUM(I17:I23) -> 2165 | J24: =SUM(J17:J23) -> 2128 | ... L24: =SUM(L17:L23) -> 15763
B25: Gross Profit | C25: =C14-C24 -> 1370 | D25: =D14-D24 -> 1338 | E25: =E14-E24 -> 1430 | F25: =F14-F24 -> 1475 | G25: =G14-G24 -> 1565 | H25: =H14-H24 -> 1660 | I25: =I14-I24 -> 1715 | J25: =J14-J24 -> 1647 | ... L25: =L14-L24 -> 13633
B26: Gross Margin | C26: =IF(C14=0,0,C25/C14) -> 0.49709724 | D26: =IF(D14=0,0,D25/D14) -> 0.49721293 | E26: =IF(E14=0,0,E25/E14) -> 0.49124012 | F26: =IF(F14=0,0,F25/F14) -> 0.48061258 | G26: =IF(G14=0,0,G25/G14) -> 0.46702477 | H26: =IF(H14=0,0,H25/H14) -> 0.45293315 | I26: =IF(I14=0,0,I25/I14) -> 0.44201031 | J26: =IF(J14=0,0,J25/J14) -> 0.43629139 | ... L26: =IF(L14=0,0,L25/L14) -> 0.46377058
B28: Operating Expenses
A29: 6010 | B29: CSR, Dispatch & Office Salaries | C29: 212 | D29: 212 | E29: 212 | F29: 212 | G29: 212 | H29: 212 | I29: 212 | J29: 212 | K29: 212 | L29: =SUM(C29:K29) -> 1908
A30: 6020 | B30: Branch & Corporate Management Salaries | C30: 160 | D30: 160 | E30: 160 | F30: 160 | G30: 160 | H30: 160 | I30: 160 | J30: 160 | K30: 160 | L30: =SUM(C30:K30) -> 1440
A31: 6030 | B31: Office Payroll Taxes & Benefits | C31: 74 | D31: 74 | E31: 74 | F31: 74 | G31: 74 | H31: 74 | I31: 74 | J31: 74 | K31: 74 | L31: =SUM(C31:K31) -> 666
A32: 6110 | B32: Marketing, Lead Gen & Digital Ads | C32: 162 | D32: 159 | E32: 172 | F32: 181 | G32: 197 | H32: 216 | I32: 229 | J32: 223 | K32: 194 | L32: =SUM(C32:K32) -> 1733
A33: 6120 | B33: Field Service Software & Call Center | C33: 48 | D33: 48 | E33: 48 | F33: 48 | G33: 48 | H33: 48 | I33: 48 | J33: 48 | K33: 48 | L33: =SUM(C33:K33) -> 432
A34: 6210 | B34: Branch Facility Rent | C34: 62 | D34: 62 | E34: 62 | F34: 62 | G34: 62 | H34: 62 | I34: 62 | J34: 62 | K34: 62 | L34: =SUM(C34:K34) -> 558
A35: 6220 | B35: Utilities & Telecom | C35: 14 | D35: 14 | E35: 14 | F35: 14 | G35: 14 | H35: 14 | I35: 14 | J35: 14 | K35: 14 | L35: =SUM(C35:K35) -> 126
A36: 6310 | B36: General Liability, Auto & Umbrella Insurance | C36: 41 | D36: 41 | E36: 41 | F36: 41 | G36: 41 | H36: 41 | I36: 41 | J36: 41 | K36: 41 | L36: =SUM(C36:K36) -> 369
A37: 6410 | B37: Accounting, Legal & Professional Fees | C37: 22 | D37: 22 | E37: 22 | F37: 22 | G37: 22 | H37: 22 | I37: 22 | J37: 22 | K37: 22 | L37: =SUM(C37:K37) -> 198
A38: 6420 | B38: Sponsor Management Fee | C38: 50 | D38: 50 | E38: 50 | F38: 50 | G38: 50 | H38: 50 | I38: 50 | J38: 50 | K38: 50 | L38: =SUM(C38:K38) -> 450
A39: 6510 | B39: Technician Training & Recruiting | C39: 16 | D39: 16 | E39: 16 | F39: 16 | G39: 16 | H39: 24 | I39: 24 | J39: 24 | K39: 24 | L39: =SUM(C39:K39) -> 176
A40: 6900 | B40: Other G&A | C40: 30 | D40: 30 | E40: 30 | F40: 30 | G40: 30 | H40: 30 | I40: 30 | J40: 30 | K40: 30 | L40: =SUM(C40:K40) -> 270
B41: Total Operating Expenses | C41: =SUM(C29:C40) -> 891 | D41: =SUM(D29:D40) -> 888 | E41: =SUM(E29:E40) -> 901 | F41: =SUM(F29:F40) -> 910 | G41: =SUM(G29:G40) -> 926 | H41: =SUM(H29:H40) -> 953 | I41: =SUM(I29:I40) -> 966 | J41: =SUM(J29:J40) -> 960 | ... L41: =SUM(L29:L40) -> 8326
B42: EBITDA | C42: =C25-C41 -> 479 | D42: =D25-D41 -> 450 | E42: =E25-E41 -> 529 | F42: =F25-F41 -> 565 | G42: =G25-G41 -> 639 | H42: =H25-H41 -> 707 | I42: =I25-I41 -> 749 | J42: =J25-J41 -> 687 | ... L42: =L25-L41 -> 5307
B43: EBITDA Margin | C43: =IF(C14=0,0,C42/C14) -> 0.17380261 | D43: =IF(D14=0,0,D42/D14) -> 0.16722408 | E43: =IF(E14=0,0,E42/E14) -> 0.18172449 | F43: =IF(F14=0,0,F42/F14) -> 0.18409906 | G43: =IF(G14=0,0,G42/G14) -> 0.19068935 | H43: =IF(H14=0,0,H42/H14) -> 0.19290587 | I43: =IF(I14=0,0,I42/I14) -> 0.19304124 | J43: =IF(J14=0,0,J42/J14) -> 0.18198675 | ... L43: =IF(L14=0,0,L42/L14) -> 0.18053477
...
